Workbook

Sheet Full Mobility Curves
A1: Aware1 | C1: Aware2 | E1: Aware3 | G1: Aware4 | I1: Aware5 | K1: Learn1 | M1: Learn2 | O1: Learn3 | Q1: Learn4 | S1: Learn5 | U1: Rich1 | W1: Rich2 | Y1: Rich3 | AA1: Rich4 | AC1: Rich5 | AE1: Baserun1 | AG1: Baserun2 | AI1: Baserun3 | AK1: Baserun4 | AM1: Baserun5 | AO1: Aware Full | AQ1: Learn Full | AS1: Rich Full | AU1: Baseline Full
A2: New cases | B2: Mobility | C2: New cases | D2: Mobility | E2: New cases | F2: Mobility | G2: New cases | H2: Mobility | I2: New cases | J2: Mobility | K2: New cases | L2: Mobility | M2: New cases | N2: Mobility | O2: New cases | P2: Mobility | Q2: New cases | R2: Mobility | S2: New cases | T2: Mobility | U2: New cases | V2: Mobility | W2: New cases | X2: Mobility | Y2: New cases | Z2: Mobility | AA2: New cases | AB2: Mobility | AC2: New cases | AD2: Mobility | AE2: New cases | AF2: Mobility | AG2: New cases | AH2: Mobility | AI2: New cases | AJ2: Mobility | AK2: New cases | AL2: Mobility | AM2: New cases | AN2: Mobility | AO2: New Cases | AP2: Mobility | AQ2: New Cases | AR2: Mobility | AS2: New Cases | AT2: Mobility | AU2: New Cases | AV2: Mobility
A3: =Aware1!$K2/100 -> 0 | B3: =Aware1!$G3/100 -> 1 | C3: =Aware2!$K2/100 -> 0 | D3: =Aware2!$G3/100 -> 1 | E3: =Aware3!$K2/100 -> 0 | F3: =Aware3!$G3/100 -> 1 | G3: =Aware4!$K2/100 -> 0 | H3: =Aware4!$G3/100 -> 1 | I3: =Aware5!$K2/100 -> 0 | J3: =Aware5!$G3/100 -> 1 | K3: =Learn1!$K2/100 -> 0 | L3: =Learn1!$G3/100 -> 1 | M3: =Learn2!$K2/100 -> 0 | N3: =Learn2!$G3/100 -> 1 | O3: =Learn3!$K2/100 -> 0 | P3: =Learn3!$G3/100 -> 0.98 | Q3: =Learn4!$K2/100 -> 0 | R3: =Learn4!$G3/100 -> 0.98 | S3: =Learn5!$K2/100 -> 0 | T3: =Learn5!$G3/100 -> 0.98 | U3: =Rich1!$K2/100 -> 0 | V3: =Rich1!$G3/100 -> 0.99 | W3: =Rich2!$K2/100 -> 0 | X3: =Rich2!$G3/100 -> 0.98 | Y3: =Rich3!$K2/100 -> 0 | Z3: =Rich3!$G3/100 -> 0.95 | AA3: =Rich4!$K2/100 -> 0 | AB3: =Rich4!$G3/100 -> 0.98 | AC3: =Rich5!$K2/100 -> 0 | AD3: =Rich5!$G3/100 -> 0.98 | AE3: =Baserun1!$K2/100 -> 0 | AF3: =Baserun1!$G3/100 -> 1 | AG3: =Baserun2!$K2/100 -> 0 | AH3: =Baserun2!$G3/100 -> 1 | AI3: =Baserun3!$K2/100 -> 0 | AJ3: =Baserun3!$G3/100 -> 1 | AK3: =Baserun4!$K2/100 -> 0 | AL3: =Baserun4!$G3/100 -> 1 | AM3: =Baserun5!$K2/100 -> 0 | AN3: =Baserun5!$G3/100 -> 0.99 | AO3: =A3 -> 0 | AP3: =B3 -> 1 | AQ3: =K3 -> 0 | AR3: =L3 -> 1 | AS3: =U3 -> 0 | AT3: =V3 -> 0.99 | AU3: =AE3 -> 0 | AV3: =AF3 -> 1
A4: =Aware1!$K3/100 -> 0 | B4: =Aware1!$G4/100 -> 1 | C4: =Aware2!$K3/100 -> 0 | D4: =Aware2!$G4/100 -> 1 | E4: =Aware3!$K3/100 -> 0 | F4: =Aware3!$G4/100 -> 1 | G4: =Aware4!$K3/100 -> 0 | H4: =Aware4!$G4/100 -> 1 | I4: =Aware5!$K3/100 -> 0 | J4: =Aware5!$G4/100 -> 1 | K4: =Learn1!$K3/100 -> 0 | L4: =Learn1!$G4/100 -> 0.99 | M4: =Learn2!$K3/100 -> 0 | N4: =Learn2!$G4/100 -> 1 | O4: =Learn3!$K3/100 -> 0 | P4: =Learn3!$G4/100 -> 0.98 | Q4: =Learn4!$K3/100 -> 0 | R4: =Learn4!$G4/100 -> 0.98 | S4: =Learn5!$K3/100 -> 0 | T4: =Learn5!$G4/100 -> 0.98 | U4: =Rich1!$K3/100 -> 0 | V4: =Rich1!$G4/100 -> 0.99 | W4: =Rich2!$K3/100 -> 0 | X4: =Rich2!$G4/100 -> 0.97 | Y4: =Rich3!$K3/100 -> 0 | Z4: =Rich3!$G4/100 -> 0.95 | AA4: =Rich4!$K3/100 -> 0 | AB4: =Rich4!$G4/100 -> 0.95 | AC4: =Rich5!$K3/100 -> 0 | AD4: =Rich5!$G4/100 -> 0.98 | AE4: =Baserun1!$K3/100 -> 0 | AF4: =Baserun1!$G4/100 -> 1 | AG4: =Baserun2!$K3/100 -> 0 | AH4: =Baserun2!$G4/100 -> 1 | AI4: =Baserun3!$K3/100 -> 0 | AJ4: =Baserun3!$G4/100 -> 1 | AK4: =Baserun4!$K3/100 -> 0 | AL4: =Baserun4!$G4/100 -> 1 | AM4: =Baserun5!$K3/100 -> 0 | AN4: =Baserun5!$G4/100 -> 0.99 | AO4: =A4 -> 0 | AP4: =B4 -> 1 | AQ4: =K4 -> 0 | AR4: =L4 -> 0.99 | AS4: =U4 -> 0 | AT4: =V4 -> 0.99 | AU4: =AE4 -> 0 | AV4: =AF4 -> 1
A5: =Aware1!$K4/100 -> 0 | B5: =Aware1!$G5/100 -> 1 | C5: =Aware2!$K4/100 -> 0 | D5: =Aware2!$G5/100 -> 0.99 | E5: =Aware3!$K4/100 -> 0 | F5: =Aware3!$G5/100 -> 0.99 | G5: =Aware4!$K4/100 -> 0 | H5: =Aware4!$G5/100 -> 0.99 | I5: =Aware5!$K4/100 -> 0 | J5: =Aware5!$G5/100 -> 1 | K5: =Learn1!$K4/100 -> 0 | L5: =Learn1!$G5/100 -> 1 | M5: =Learn2!$K4/100 -> 0 | N5: =Learn2!$G5/100 -> 1 | O5: =Learn3!$K4/100 -> 0 | P5: =Learn3!$G5/100 -> 0.98 | Q5: =Learn4!$K4/100 -> 0 | R5: =Learn4!$G5/100 -> 0.97 | S5: =Learn5!$K4/100 -> 0 | T5: =Learn5!$G5/100 -> 0.98 | U5: =Rich1!$K4/100 -> 0 | V5: =Rich1!$G5/100 -> 0.97 | W5: =Rich2!$K4/100 -> 0 | X5: =Rich2!$G5/100 -> 0.97 | Y5: =Rich3!$K4/100 -> 0 | Z5: =Rich3!$G5/100 -> 0.95 | AA5: =Rich4!$K4/100 -> 0 | AB5: =Rich4!$G5/100 -> 0.98 | AC5: =Rich5!$K4/100 -> 0 | AD5: =Rich5!$G5/100 -> 0.96 | AE5: =Baserun1!$K4/100 -> 0 | AF5: =Baserun1!$G5/100 -> 1 | AG5: =Baserun2!$K4/100 -> 0 | AH5: =Baserun2!$G5/100 -> 0.99 | AI5: =Baserun3!$K4/100 -> 0 | AJ5: =Baserun3!$G5/100 -> 0.99 | AK5: =Baserun4!$K4/100 -> 0 | AL5: =Baserun4!$G5/100 -> 0.99 | AM5: =Baserun5!$K4/100 -> 0 | AN5: =Baserun5!$G5/100 -> 0.99 | AO5: =A5 -> 0 | AP5: =B5 -> 1 | AQ5: =K5 -> 0 | AR5: =L5 -> 1 | AS5: =U5 -> 0 | AT5: =V5 -> 0.97 | AU5: =AE5 -> 0 | AV5: =AF5 -> 1
A6: =Aware1!$K5/100 -> 0.02 | B6: =Aware1!$G6/100 -> 0.34 | C6: =Aware2!$K5/100 -> 0.02 | D6: =Aware2!$G6/100 -> 0.27 | E6: =Aware3!$K5/100 -> 0.02 | F6: =Aware3!$G6/100 -> 0.28 | G6: =Aware4!$K5/100 -> 0.02 | H6: =Aware4!$G6/100 -> 0.32 | I6: =Aware5!$K5/100 -> 0.02 | J6: =Aware5!$G6/100 -> 0.34 | K6: =Learn1!$K5/100 -> 0.02 | L6: =Learn1!$G6/100 -> 0.19 | M6: =Learn2!$K5/100 -> 0.02 | N6: =Learn2!$G6/100 -> 0.11 | O6: =Learn3!$K5/100 -> 0.02 | P6: =Learn3!$G6/100 -> 0.05 | Q6: =Learn4!$K5/100 -> 0.02 | R6: =Learn4!$G6/100 -> 0.14 | S6: =Learn5!$K5/100 -> 0.02 | T6: =Learn5!$G6/100 -> 0.2 | U6: =Rich1!$K5/100 -> 0.02 | V6: =Rich1!$G6/100 -> 0.5 | W6: =Rich2!$K5/100 -> 0.02 | X6: =Rich2!$G6/100 -> 0.54 | Y6: =Rich3!$K5/100 -> 0.02 | Z6: =Rich3!$G6/100 -> 0.54 | AA6: =Rich4!$K5/100 -> 0.02 | AB6: =Rich4!$G6/100 -> 0.48 | AC6: =Rich5!$K5/100 -> 0.02 | AD6: =Rich5!$G6/100 -> 0.41 | AE6: =Baserun1!$K5/100 -> 0.02 | AF6: =Baserun1!$G6/100 -> 0.39 | AG6: =Baserun2!$K5/100 -> 0.02 | AH6: =Baserun2!$G6/100 -> 0.37 | AI6: =Baserun3!$K5/100 -> 0.02 | AJ6: =Baserun3!$G6/100 -> 0.38 | AK6: =Baserun4!$K5/100 -> 0.02 | AL6: =Baserun4!$G6/100 -> 0.37 | AM6: =Baserun5!$K5/100 -> 0.02 | AN6: =Baserun5!$G6/100 -> 0.3 | AO6: =A6 -> 0.02 | AP6: =B6 -> 0.34 | AQ6: =K6 -> 0.02 | AR6: =L6 -> 0.19 | AS6: =U6 -> 0.02 | AT6: =V6 -> 0.5 | AU6: =AE6 -> 0.02 | AV6: =AF6 -> 0.39
A7: =Aware1!$K6/100 -> 0.03 | B7: =Aware1!$G7/100 -> 0.33 | C7: =Aware2!$K6/100 -> 0 | D7: =Aware2!$G7/100 -> 0.98 | E7: =Aware3!$K6/100 -> 0 | F7: =Aware3!$G7/100 -> 0.98 | G7: =Aware4!$K6/100 -> 0.02 | H7: =Aware4!$G7/100 -> 0.28 | I7: =Aware5!$K6/100 -> 0.02 | J7: =Aware5!$G7/100 -> 0.34 | K7: =Learn1!$K6/100 -> 0 | L7: =Learn1!$G7/100 -> 0.98 | M7: =Learn2!$K6/100 -> 0 | N7: =Learn2!$G7/100 -> 0.98 | O7: =Learn3!$K6/100 -> 0.01 | P7: =Learn3!$G7/100 -> 0.17 | Q7: =Learn4!$K6/100 -> 0.02 | R7: =Learn4!$G7/100 -> 0.14 | S7: =Learn5!$K6/100 -> 0.01 | T7: =Learn5!$G7/100 -> 0.26 | U7: =Rich1!$K6/100 -> 0.03 | V7: =Rich1!$G7/100 -> 0.45 | W7: =Rich2!$K6/100 -> 0.01 | X7: =Rich2!$G7/100 -> 0.79 | Y7: =Rich3!$K6/100 -> 0.02 | Z7: =Rich3!$G7/100 -> 0.49 | AA7: =Rich4!$K6/100 -> 0.03 | AB7: =Rich4!$G7/100 -> 0.42 | AC7: =Rich5!$K6/100 -> 0.05 | AD7: =Rich5!$G7/100 -> 0.41 | AE7: =Baserun1!$K6/100 -> 0 | AF7: =Baserun1!$G7/100 -> 0.97 | AG7: =Baserun2!$K6/100 -> 0.04 | AH7: =Baserun2!$G7/100 -> 0.36 | AI7: =Baserun3!$K6/100 -> 0.01 | AJ7: =Baserun3!$G7/100 -> 0.52 | AK7: =Baserun4!$K6/100 -> 0.03 | AL7: =Baserun4!$G7/100 -> 0.42 | AM7: =Baserun5!$K6/100 -> 0.01 | AN7: =Baserun5!$G7/100 -> 0.46 | AO7: =A7 -> 0.03 | AP7: =B7 -> 0.33 | AQ7: =K7 -> 0 | AR7: =L7 -> 0.98 | AS7: =U7 -> 0.03 | AT7: =V7 -> 0.45 | AU7: =AE7 -> 0 | AV7: =AF7 -> 0.97
A8: =Aware1!$K7/100 -> 0.02 | B8: =Aware1!$G8/100 -> 0.33 | C8: =Aware2!$K7/100 -> 0 | D8: =Aware2!$G8/100 -> 0.99 | E8: =Aware3!$K7/100 -> 0.01 | F8: =Aware3!$G8/100 -> 0.5 | G8: =Aware4!$K7/100 -> 0.04 | H8: =Aware4!$G8/100 -> 0.28 | I8: =Aware5!$K7/100 -> 0.05 | J8: =Aware5!$G8/100 -> 0.2 | K8: =Learn1!$K7/100 -> 0.01 | L8: =Learn1!$G8/100 -> 0.23 | M8: =Learn2!$K7/100 -> 0.03 | N8: =Learn2!$G8/100 -> 0.2 | O8: =Learn3!$K7/100 -> 0.01 | P8: =Learn3!$G8/100 -> 0.16 | Q8: =Learn4!$K7/100 -> 0.03 | R8: =Learn4!$G8/100 -> 0.15 | S8: =Learn5!$K7/100 -> 0.04 | T8: =Learn5!$G8/100 -> 0.18 | U8: =Rich1!$K7/100 -> 0.04 | V8: =Rich1!$G8/100 -> 0.47 | W8: =Rich2!$K7/100 -> 0.02 | X8: =Rich2!$G8/100 -> 0.51 | Y8: =Rich3!$K7/100 -> 0 | Z8: =Rich3!$G8/100 -> 0.93 | AA8: =Rich4!$K7/100 -> 0.05 | AB8: =Rich4!$G8/100 -> 0.4 | AC8: =Rich5!$K7/100 -> 0.05 | AD8: =Rich5!$G8/100 -> 0.45 | AE8: =Baserun1!$K7/100 -> 0.05 | AF8: =Baserun1!$G8/100 -> 0.37 | AG8: =Baserun2!$K7/100 -> 0.09 | AH8: =Baserun2!$G8/100 -> 0.28 | AI8: =Baserun3!$K7/100 -> 0.03 | AJ8: =Baserun3!$G8/100 -> 0.37 | AK8: =Baserun4!$K7/100 -> 0.04 | AL8: =Baserun4!$G8/100 -> 0.34 | AM8: =Baserun5!$K7/100 -> 0.02 | AN8: =Baserun5!$G8/100 -> 0.29 | AO8: =A8 -> 0.02 | AP8: =B8 -> 0.33 | AQ8: =K8 -> 0.01 | AR8: =L8 -> 0.23 | AS8: =U8 -> 0.04 | AT8: =V8 -> 0.47 | AU8: =AE8 -> 0.05 | AV8: =AF8 -> 0.37
A9: =Aware1!$K8/100 -> 0.07 | B9: =Aware1!$G9/100 -> 0.25 | C9: =Aware2!$K8/100 -> 0.01 | D9: =Aware2!$G9/100 -> 0.61 | E9: =Aware3!$K8/100 -> 0.02 | F9: =Aware3!$G9/100 -> 0.3 | G9: =Aware4!$K8/100 -> 0.03 | H9: =Aware4!$G9/100 -> 0.33 | I9: =Aware5!$K8/100 -> 0.08 | J9: =Aware5!$G9/100 -> 0.2 | K9: =Learn1!$K8/100 -> 0.04 | L9: =Learn1!$G9/100 -> 0.14 | M9: =Learn2!$K8/100 -> 0.05 | N9: =Learn2!$G9/100 -> 0.13 | O9: =Learn3!$K8/100 -> 0.06 | P9: =Learn3!$G9/100 -> 0.1 | Q9: =Learn4!$K8/100 -> 0.06 | R9: =Learn4!$G9/100 -> 0.14 | S9: =Learn5!$K8/100 -> 0.04 | T9: =Learn5!$G9/100 -> 0.19 | U9: =Rich1!$K8/100 -> 0.04 | V9: =Rich1!$G9/100 -> 0.49 | W9: =Rich2!$K8/100 -> 0.04 | X9: =Rich2!$G9/100 -> 0.49 | Y9: =Rich3!$K8/100 -> 0 | Z9: =Rich3!$G9/100 -> 0.93 | AA9: =Rich4!$K8/100 -> 0.06 | AB9: =Rich4!$G9/100 -> 0.36 | AC9: =Rich5!$K8/100 -> 0.06 | AD9: =Rich5!$G9/100 -> 0.54 | AE9: =Baserun1!$K8/100 -> 0.08 | AF9: =Baserun1!$G9/100 -> 0.3 | AG9: =Baserun2!$K8/100 -> 0.1 | AH9: =Baserun2!$G9/100 -> 0.14 | AI9: =Baserun3!$K8/100 -> 0.03 | AJ9: =Baserun3!$G9/100 -> 0.34 | AK9: =Baserun4!$K8/100 -> 0.06 | AL9: =Baserun4!$G9/100 -> 0.3 | AM9: =Baserun5!$K8/100 -> 0.06 | AN9: =Baserun5!$G9/100 -> 0.26 | AO9: =A9 -> 0.07 | AP9: =B9 -> 0.25 | AQ9: =K9 -> 0.04 | AR9: =L9 -> 0.14 | AS9: =U9 -> 0.04 | AT9: =V9 -> 0.49 | AU9: =AE9 -> 0.08 | AV9: =AF9 -> 0.3
A10: =Aware1!$K9/100 -> 0.03 | B10: =Aware1!$G10/100 -> 0.32 | C10: =Aware2!$K9/100 -> 0 | D10: =Aware2!$G10/100 -> 0.99 | E10: =Aware3!$K9/100 -> 0 | F10: =Aware3!$G10/100 -> 0.98 | G10: =Aware4!$K9/100 -> 0.01 | H10: =Aware4!$G10/100 -> 0.52 | I10: =Aware5!$K9/100 -> 0.01 | J10: =Aware5!$G10/100 -> 0.47 | K10: =Learn1!$K9/100 -> 0.04 | L10: =Learn1!$G10/100 -> 0.15 | M10: =Learn2!$K9/100 -> 0.03 | N10: =Learn2!$G10/100 -> 0.14 | O10: =Learn3!$K9/100 -> 0 | P10: =Learn3!$G10/100 -> 0.93 | Q10: =Learn4!$K9/100 -> 0 | R10: =Learn4!$G10/100 -> 0.93 | S10: =Learn5!$K9/100 -> 0.01 | T10: =Learn5!$G10/100 -> 0.24 | U10: =Rich1!$K9/100 -> 0.05 | V10: =Rich1!$G10/100 -> 0.39 | W10: =Rich2!$K9/100 -> 0.05 | X10: =Rich2!$G10/100 -> 0.51 | Y10: =Rich3!$K9/100 -> 0.03 | Z10: =Rich3!$G10/100 -> 0.43 | AA10: =Rich4!$K9/100 -> 0.07 | AB10: =Rich4!$G10/100 -> 0.34 | AC10: =Rich5!$K9/100 -> 0.02 | AD10: =Rich5!$G10/100 -> 0.46 | AE10: =Baserun1!$K9/100 -> 0.04 | AF10: =Baserun1!$G10/100 -> 0.3 | AG10: =Baserun2!$K9/100 -> 0.06 | AH10: =Baserun2!$G10/100 -> 0.26 | AI10: =Baserun3!$K9/100 -> 0.03 | AJ10: =Baserun3!$G10/100 -> 0.29 | AK10: =Baserun4!$K9/100 -> 0.03 | AL10: =Baserun4!$G10/100 -> 0.32 | AM10: =Baserun5!$K9/100 -> 0.02 | AN10: =Baserun5!$G10/100 -> 0.21 | AO10: =A10 -> 0.03 | AP10: =B10 -> 0.32 | AQ10: =K10 -> 0.04 | AR10: =L10 -> 0.15 | AS10: =U10 -> 0.05 | AT10: =V10 -> 0.39 | AU10: =AE10 -> 0.04 | AV10: =AF10 -> 0.3
A11: =Aware1!$K10/100 -> 0 | B11: =Aware1!$G11/100 -> 0.95 | C11: =Aware2!$K10/100 -> 0.01 | D11: =Aware2!$G11/100 -> 0.56 | E11: =Aware3!$K10/100 -> 0.01 | F11: =Aware3!$G11/100 -> 0.47 | G11: =Aware4!$K10/100 -> 0.03 | H11: =Aware4!$G11/100 -> 0.33 | I11: =Aware5!$K10/100 -> 0.09 | J11: =Aware5!$G11/100 -> 0.09 | K11: =Learn1!$K10/100 -> 0.09 | L11: =Learn1!$G11/100 -> 0.1 | M11: =Learn2!$K10/100 -> 0.09 | N11: =Learn2!$G11/100 -> 0.14 | O11: =Learn3!$K10/100 -> 0 | P11: =Learn3!$G11/100 -> 0.99 | Q11: =Learn4!$K10/100 -> 0 | R11: =Learn4!$G11/100 -> 0.98 | S11: =Learn5!$K10/100 -> 0.02 | T11: =Learn5!$G11/100 -> 0.17 | U11: =Rich1!$K10/100 -> 0.06 | V11: =Rich1!$G11/100 -> 0.41 | W11: =Rich2!$K10/100 -> 0.07 | X11: =Rich2!$G11/100 -> 0.35 | Y11: =Rich3!$K10/100 -> 0.03 | Z11: =Rich3!$G11/100 -> 0.46 | AA11: =Rich4!$K10/100 -> 0.07 | AB11: =Rich4!$G11/100 -> 0.33 | AC11: =Rich5!$K10/100 -> 0.05 | AD11: =Rich5!$G11/100 -> 0.37 | AE11: =Baserun1!$K10/100 -> 0.15 | AF11: =Baserun1!$G11/100 -> 0.22 | AG11: =Baserun2!$K10/100 -> 0.05 | AH11: =Baserun2!$G11/100 -> 0.18 | AI11: =Baserun3!$K10/100 -> 0.02 | AJ11: =Baserun3!$G11/100 -> 0.32 | AK11: =Baserun4!$K10/100 -> 0.06 | AL11: =Baserun4!$G11/100 -> 0.21 | AM11: =Baserun5!$K10/100 -> 0.06 | AN11: =Baserun5!$G11/100 -> 0.23 | AO11: =A11 -> 0 | AP11: =B11 -> 0.95 | AQ11: =K11 -> 0.09 | AR11: =L11 -> 0.1 | AS11: =U11 -> 0.06 | AT11: =V11 -> 0.41 | AU11: =AE11 -> 0.15 | AV11: =AF11 -> 0.22
A12: =Aware1!$K11/100 -> 0.03 | B12: =Aware1!$G12/100 -> 0.28 | C12: =Aware2!$K11/100 -> 0.03 | D12: =Aware2!$G12/100 -> 0.29 | E12: =Aware3!$K11/100 -> 0.01 | F12: =Aware3!$G12/100 -> 0.48 | G12: =Aware4!$K11/100 -> 0.01 | H12: =Aware4!$G12/100 -> 0.57 | I12: =Aware5!$K11/100 -> 0.05 | J12: =Aware5!$G12/100 -> 0.12 | K12: =Learn1!$K11/100 -> 0.05 | L12: =Learn1!$G12/100 -> 0.13 | M12: =Learn2!$K11/100 -> 0.04 | N12: =Learn2!$G12/100 -> 0.18 | O12: =Learn3!$K11/100 -> 0 | P12: =Learn3!$G12/100 -> 0.98 | Q12: =Learn4!$K11/100 -> 0 | R12: =Learn4!$G12/100 -> 0.98 | S12: =Learn5!$K11/100 -> 0.03 | T12: =Learn5!$G12/100 -> 0.14 | U12: =Rich1!$K11/100 -> 0.1 | V12: =Rich1!$G12/100 -> 0.46 | W12: =Rich2!$K11/100 -> 0.08 | X12: =Rich2!$G12/100 -> 0.39 | Y12: =Rich3!$K11/100 -> 0.07 | Z12: =Rich3!$G12/100 -> 0.35 | AA12: =Rich4!$K11/100 -> 0.06 | AB12: =Rich4!$G12/100 -> 0.26 | AC12: =Rich5!$K11/100 -> 0.09 | AD12: =Rich5!$G12/100 -> 0.4 | AE12: =Baserun1!$K11/100 -> 0.07 | AF12: =Baserun1!$G12/100 -> 0.2 | AG12: =Baserun2!$K11/100 -> 0.07 | AH12: =Baserun2!$G12/100 -> 0.27 | AI12: =Baserun3!$K11/100 -> 0.04 | AJ12: =Baserun3!$G12/100 -> 0.35 | AK12: =Baserun4!$K11/100 -> 0.07 | AL12: =Baserun4!$G12/100 -> 0.23 | AM12: =Baserun5!$K11/100 -> 0.04 | AN12: =Baserun5!$G12/100 -> 0.26 | AO12: =A12 -> 0.03 | AP12: =B12 -> 0.28 | AQ12: =K12 -> 0.05 | AR12: =L12 -> 0.13 | AS12: =U12 -> 0.1 | AT12: =V12 -> 0.46 | AU12: =AE12 -> 0.07 | AV12: =AF12 -> 0.2
A13: =Aware1!$K12/100 -> 0.04 | B13: =Aware1!$G13/100 -> 0.19 | C13: =Aware2!$K12/100 -> 0.02 | D13: =Aware2!$G13/100 -> 0.25 | E13: =Aware3!$K12/100 -> 0.02 | F13: =Aware3!$G13/100 -> 0.23 | G13: =Aware4!$K12/100 -> 0.04 | H13: =Aware4!$G13/100 -> 0.24 | I13: =Aware5!$K12/100 -> 0.04 | J13: =Aware5!$G13/100 -> 0.18 | K13: =Learn1!$K12/100 -> 0.03 | L13: =Learn1!$G13/100 -> 0.14 | M13: =Learn2!$K12/100 -> 0.03 | N13: =Learn2!$G13/100 -> 0.1 | O13: =Learn3!$K12/100 -> 0 | P13: =Learn3!$G13/100 -> 0.98 | Q13: =Learn4!$K12/100 -> 0.03 | R13: =Learn4!$G13/100 -> 0.19 | S13: =Learn5!$K12/100 -> 0.03 | T13: =Learn5!$G13/100 -> 0.11 | U13: =Rich1!$K12/100 -> 0.04 | V13: =Rich1!$G13/100 -> 0.42 | W13: =Rich2!$K12/100 -> 0.06 | X13: =Rich2!$G13/100 -> 0.36 | Y13: =Rich3!$K12/100 -> 0.1 | Z13: =Rich3!$G13/100 -> 0.41 | AA13: =Rich4!$K12/100 -> 0.06 | AB13: =Rich4!$G13/100 -> 0.3 | AC13: =Rich5!$K12/100 -> 0.12 | AD13: =Rich5!$G13/100 -> 0.45 | AE13: =Baserun1!$K12/100 -> 0.07 | AF13: =Baserun1!$G13/100 -> 0.18 | AG13: =Baserun2!$K12/100 -> 0.02 | AH13: =Baserun2!$G13/100 -> 0.26 | AI13: =Baserun3!$K12/100 -> 0.05 | AJ13: =Baserun3!$G13/100 -> 0.41 | AK13: =Baserun4!$K12/100 -> 0.04 | AL13: =Baserun4!$G13/100 -> 0.25 | AM13: =Baserun5!$K12/100 -> 0.03 | AN13: =Baserun5!$G13/100 -> 0.26 | AO13: =A13 -> 0.04 | AP13: =B13 -> 0.19 | AQ13: =K13 -> 0.03 | AR13: =L13 -> 0.14 | AS13: =U13 -> 0.04 | AT13: =V13 -> 0.42 | AU13: =AE13 -> 0.07 | AV13: =AF13 -> 0.18
A14: =Aware1!$K13/100 -> 0.05 | B14: =Aware1!$G14/100 -> 0.26 | C14: =Aware2!$K13/100 -> 0.05 | D14: =Aware2!$G14/100 -> 0.23 | E14: =Aware3!$K13/100 -> 0.08 | F14: =Aware3!$G14/100 -> 0.2 | G14: =Aware4!$K13/100 -> 0.02 | H14: =Aware4!$G14/100 -> 0.28 | I14: =Aware5!$K13/100 -> 0.1 | J14: =Aware5!$G14/100 -> 0.16 | K14: =Learn1!$K13/100 -> 0.03 | L14: =Learn1!$G14/100 -> 0.14 | M14: =Learn2!$K13/100 -> 0.05 | N14: =Learn2!$G14/100 -> 0.14 | O14: =Learn3!$K13/100 -> 0.03 | P14: =Learn3!$G14/100 -> 0.15 | Q14: =Learn4!$K13/100 -> 0.04 | R14: =Learn4!$G14/100 -> 0.14 | S14: =Learn5!$K13/100 -> 0.07 | T14: =Learn5!$G14/100 -> 0.09 | U14: =Rich1!$K13/100 -> 0.05 | V14: =Rich1!$G14/100 -> 0.38 | W14: =Rich2!$K13/100 -> 0.11 | X14: =Rich2!$G14/100 -> 0.36 | Y14: =Rich3!$K13/100 -> 0.08 | Z14: =Rich3!$G14/100 -> 0.39 | AA14: =Rich4!$K13/100 -> 0.07 | AB14: =Rich4!$G14/100 -> 0.24 | AC14: =Rich5!$K13/100 -> 0.05 | AD14: =Rich5!$G14/100 -> 0.39 | AE14: =Baserun1!$K13/100 -> 0.08 | AF14: =Baserun1!$G14/100 -> 0.17 | AG14: =Baserun2!$K13/100 -> 0.05 | AH14: =Baserun2!$G14/100 -> 0.23 | AI14: =Baserun3!$K13/100 -> 0.02 | AJ14: =Baserun3!$G14/100 -> 0.3 | AK14: =Baserun4!$K13/100 -> 0.07 | AL14: =Baserun4!$G14/100 -> 0.23 | AM14: =Baserun5!$K13/100 -> 0.05 | AN14: =Baserun5!$G14/100 -> 0.21 | AO14: =A14 -> 0.05 | AP14: =B14 -> 0.26 | AQ14: =K14 -> 0.03 | AR14: =L14 -> 0.14 | AS14: =U14 -> 0.05 | AT14: =V14 -> 0.38 | AU14: =AE14 -> 0.08 | AV14: =AF14 -> 0.17
... A23: =Aware1!$K22/100 -> 0 | B23: =Aware1!$G23/100 -> 1 | C23: =Aware2!$K22/100 -> 0 | D23: =Aware2!$G23/100 -> 0.99 | E23: =Aware3!$K22/100 -> 0.01 | F23: =Aware3!$G23/100 -> 0.44 | G23: =Aware4!$K22/100 -> 0 | H23: =Aware4!$G23/100 -> 0.97 | I23: =Aware5!$K22/100 -> 0 | J23: =Aware5!$G23/100 -> 0.99 | K23: =Learn1!$K22/100 -> 0.01 | L23: =Learn1!$G23/100 -> 0.23 | M23: =Learn2!$K22/100 -> 0 | N23: =Learn2!$G23/100 -> 0.99 | O23: =Learn3!$K22/100 -> 0 | P23: =Learn3!$G23/100 -> 0.97 | Q23: =Learn4!$K22/100 -> 0.03 | R23: =Learn4!$G23/100 -> 0.19 | S23: =Learn5!$K22/100 -> 0.01 | T23: =Learn5!$G23/100 -> 0.26 | U23: =Rich1!$K22/100 -> 0 | V23: =Rich1!$G23/100 -> 0.98 | W23: =Rich2!$K22/100 -> 0 | X23: =Rich2!$G23/100 -> 0.96 | Y23: =Rich3!$K22/100 -> 0.02 | Z23: =Rich3!$G23/100 -> 0.52 | AA23: =Rich4!$K22/100 -> 0.01 | AB23: =Rich4!$G23/100 -> 0.64 | AC23: =Rich5!$K22/100 -> 0 | AD23: =Rich5!$G23/100 -> 0.96 | AE23: =Baserun1!$K22/100 -> 0 | AF23: =Baserun1!$G23/100 -> 0.98 | AG23: =Baserun2!$K22/100 -> 0 | AH23: =Baserun2!$G23/100 -> 0.99 | AI23: =Baserun3!$K22/100 -> 0.01 | AJ23: =Baserun3!$G23/100 -> 0.59 | AK23: =Baserun4!$K22/100 -> 0 | AL23: =Baserun4!$G23/100 -> 0.99 | AM23: =Baserun5!$K22/100 -> 0 | AN23: =Baserun5!$G23/100 -> 0.98 | AO23: =A23 -> 0 | AP23: =B23 -> 1 | AQ23: =K23 -> 0.01 | AR23: =L23 -> 0.23 | AS23: =U23 -> 0 | AT23: =V23 -> 0.98 | AU23: =AE23 -> 0 | AV23: =AF23 -> 0.98
A24: =Aware1!$K23/100 -> 0 | B24: =Aware1!$G24/100 -> 1 | C24: =Aware2!$K23/100 -> 0 | D24: =Aware2!$G24/100 -> 0.99 | E24: =Aware3!$K23/100 -> 0 | F24: =Aware3!$G24/100 -> 0.96 | G24: =Aware4!$K23/100 -> 0 | H24: =Aware4!$G24/100 -> 1 | I24: =Aware5!$K23/100 -> 0 | J24: =Aware5!$G24/100 -> 0.99 | K24: =Learn1!$K23/100 -> 0 | L24: =Learn1!$G24/100 -> 0.99 | M24: =Learn2!$K23/100 -> 0.02 | N24: =Learn2!$G24/100 -> 0.13 | O24: =Learn3!$K23/100 -> 0 | P24: =Learn3!$G24/100 -> 0.98 | Q24: =Learn4!$K23/100 -> 0 | R24: =Learn4!$G24/100 -> 0.95 | S24: =Learn5!$K23/100 -> 0 | T24: =Learn5!$G24/100 -> 0.97 | U24: =Rich1!$K23/100 -> 0 | V24: =Rich1!$G24/100 -> 0.95 | W24: =Rich2!$K23/100 -> 0.01 | X24: =Rich2!$G24/100 -> 0.72 | Y24: =Rich3!$K23/100 -> 0.01 | Z24: =Rich3!$G24/100 -> 0.69 | AA24: =Rich4!$K23/100 -> 0.02 | AB24: =Rich4!$G24/100 -> 0.49 | AC24: =Rich5!$K23/100 -> 0.02 | AD24: =Rich5!$G24/100 -> 0.43 | AE24: =Baserun1!$K23/100 -> 0 | AF24: =Baserun1!$G24/100 -> 1 | AI24: =Baserun3!$K23/100 -> 0.01 | AJ24: =Baserun3!$G24/100 -> 0.62 | AK24: =Baserun4!$K23/100 -> 0 | AL24: =Baserun4!$G24/100 -> 0.98 | AM24: =Baserun5!$K23/100 -> 0.03 | AN24: =Baserun5!$G24/100 -> 0.4 | AO24: =A24 -> 0 | AP24: =B24 -> 1 | AQ24: =K24 -> 0 | AR24: =L24 -> 0.99 | AS24: =U24 -> 0 | AT24: =V24 -> 0.95 | AU24: =AE24 -> 0 | AV24: =AF24 -> 1
A25: =Aware1!$K24/100 -> 0 | B25: =Aware1!$G25/100 -> 1 | C25: =Aware2!$K24/100 -> 0.01 | D25: =Aware2!$G25/100 -> 0.6 | E25: =Aware3!$K24/100 -> 0 | F25: =Aware3!$G25/100 -> 1 | G25: =Aware4!$K24/100 -> 0 | H25: =Aware4!$G25/100 -> 1 | I25: =Aware5!$K24/100 -> 0.01 | J25: =Aware5!$G25/100 -> 0.61 | K25: =Learn1!$K24/100 -> 0.01 | L25: =Learn1!$G25/100 -> 0.22 | M25: =Learn2!$K24/100 -> 0 | N25: =Learn2!$G25/100 -> 0.98 | O25: =Learn3!$K24/100 -> 0 | P25: =Learn3!$G25/100 -> 0.98 | Q25: =Learn4!$K24/100 -> 0 | R25: =Learn4!$G25/100 -> 0.98 | S25: =Learn5!$K24/100 -> 0.01 | T25: =Learn5!$G25/100 -> 0.26 | W25: =Rich2!$K24/100 -> 0.01 | X25: =Rich2!$G25/100 -> 0.76 | Y25: =Rich3!$K24/100 -> 0.01 | Z25: =Rich3!$G25/100 -> 0.71 | AA25: =Rich4!$K24/100 -> 0.01 | AB25: =Rich4!$G25/100 -> 0.7 | AC25: =Rich5!$K24/100 -> 0.01 | AD25: =Rich5!$G25/100 -> 0.65 | AI25: =Baserun3!$K24/100 -> 0 | AJ25: =Baserun3!$G25/100 -> 0.99 | AK25: =Baserun4!$K24/100 -> 0.02 | AL25: =Baserun4!$G25/100 -> 0.35 | AM25: =Baserun5!$K24/100 -> 0 | AN25: =Baserun5!$G25/100 -> 0.96 | AO25: =A25 -> 0 | AP25: =B25 -> 1 | AQ25: =K25 -> 0.01 | AR25: =L25 -> 0.22 | AS25: =W3 -> 0 | AT25: =X3 -> 0.98 | AU25: =AG3 -> 0 | AV25: =AH3 -> 1
A26: =Aware1!$K25/100 -> 0 | B26: =Aware1!$G26/100 -> 1 | C26: =Aware2!$K25/100 -> 0 | D26: =Aware2!$G26/100 -> 1 | E26: =Aware3!$K25/100 -> 0 | F26: =Aware3!$G26/100 -> 1 | G26: =Aware4!$K25/100 -> 0 | H26: =Aware4!$G26/100 -> 1 | I26: =Aware5!$K25/100 -> 0.01 | J26: =Aware5!$G26/100 -> 0.62 | K26: =Learn1!$K25/100 -> 0 | L26: =Learn1!$G26/100 -> 0.99 | M26: =Learn2!$K25/100 -> 0 | N26: =Learn2!$G26/100 -> 1 | O26: =Learn3!$K25/100 -> 0 | P26: =Learn3!$G26/100 -> 0.98 | Q26: =Learn4!$K25/100 -> 0 | R26: =Learn4!$G26/100 -> 0.98 | S26: =Learn5!$K25/100 -> 0.02 | T26: =Learn5!$G26/100 -> 0.2 | W26: =Rich2!$K25/100 -> 0 | X26: =Rich2!$G26/100 -> 0.95 | Y26: =Rich3!$K25/100 -> 0 | Z26: =Rich3!$G26/100 -> 0.94 | AA26: =Rich4!$K25/100 -> 0.01 | AB26: =Rich4!$G26/100 -> 0.63 | AC26: =Rich5!$K25/100 -> 0 | AD26: =Rich5!$G26/100 -> 0.95 | AI26: =Baserun3!$K25/100 -> 0.02 | AJ26: =Baserun3!$G26/100 -> 0.4 | AK26: =Baserun4!$K25/100 -> 0 | AL26: =Baserun4!$G26/100 -> 0.98 | AM26: =Baserun5!$K25/100 -> 0.01 | AN26: =Baserun5!$G26/100 -> 0.48 | AO26: =A26 -> 0 | AP26: =B26 -> 1 | AQ26: =K26 -> 0 | AR26: =L26 -> 0.99 | AS26: =W4 -> 0 | AT26: =X4 -> 0.97 | AU26: =AG4 -> 0 | AV26: =AH4 -> 1
A27: =Aware1!$K26/100 -> 0.01 | B27: =Aware1!$G27/100 -> 0.6 | C27: =Aware2!$K26/100 -> 0.02 | D27: =Aware2!$G27/100 -> 0.26 | E27: =Aware3!$K26/100 -> 0 | F27: =Aware3!$G27/100 -> 0.99 | G27: =Aware4!$K26/100 -> 0 | H27: =Aware4!$G27/100 -> 1 | I27: =Aware5!$K26/100 -> 0 | J27: =Aware5!$G27/100 -> 0.98 | K27: =Learn1!$K26/100 -> 0 | L27: =Learn1!$G27/100 -> 0.99 | M27: =Learn2!$K26/100 -> 0.02 | N27: =Learn2!$G27/100 -> 0.1 | O27: =Learn3!$K26/100 -> 0.01 | P27: =Learn3!$G27/100 -> 0.17 | Q27: =Learn4!$K26/100 -> 0 | R27: =Learn4!$G27/100 -> 0.98 | S27: =Learn5!$K26/100 -> 0 | T27: =Learn5!$G27/100 -> 0.97 | W27: =Rich2!$K26/100 -> 0.02 | X27: =Rich2!$G27/100 -> 0.53 | Y27: =Rich3!$K26/100 -> 0.01 | Z27: =Rich3!$G27/100 -> 0.66 | AA27: =Rich4!$K26/100 -> 0 | AB27: =Rich4!$G27/100 -> 0.95 | AC27: =Rich5!$K26/100 -> 0.01 | AD27: =Rich5!$G27/100 -> 0.66 | AI27: =Baserun3!$K26/100 -> 0 | AJ27: =Baserun3!$G27/100 -> 0.99 | AK27: =Baserun4!$K26/100 -> 0.01 | AL27: =Baserun4!$G27/100 -> 0.53 | AM27: =Baserun5!$K26/100 -> 0.04 | AN27: =Baserun5!$G27/100 -> 0.4 | AO27: =A27 -> 0.01 | AP27: =B27 -> 0.6 | AQ27: =K27 -> 0 | AR27: =L27 -> 0.99 | AS27: =W5 -> 0 | AT27: =X5 -> 0.97 | AU27: =AG5 -> 0 | AV27: =AH5 -> 0.99
A28: =Aware1!$K27/100 -> 0 | B28: =Aware1!$G28/100 -> 0.99 | C28: =Aware2!$K27/100 -> 0.04 | D28: =Aware2!$G28/100 -> 0.3 | E28: =Aware3!$K27/100 -> 0.03 | F28: =Aware3!$G28/100 -> 0.34 | G28: =Aware4!$K27/100 -> 0.02 | H28: =Aware4!$G28/100 -> 0.31 | I28: =Aware5!$K27/100 -> 0 | J28: =Aware5!$G28/100 -> 0.99 | K28: =Learn1!$K27/100 -> 0.04 | L28: =Learn1!$G28/100 -> 0.16 | M28: =Learn2!$K27/100 -> 0 | N28: =Learn2!$G28/100 -> 0.98 | O28: =Learn3!$K27/100 -> 0 | P28: =Learn3!$G28/100 -> 0.98 | Q28: =Learn4!$K27/100 -> 0.04 | R28: =Learn4!$G28/100 -> 0.15 | S28: =Learn5!$K27/100 -> 0.02 | T28: =Learn5!$G28/100 -> 0.19 | W28: =Rich2!$K27/100 -> 0 | X28: =Rich2!$G28/100 -> 0.96 | Y28: =Rich3!$K27/100 -> 0.03 | Z28: =Rich3!$G28/100 -> 0.5 | AA28: =Rich4!$K27/100 -> 0.02 | AB28: =Rich4!$G28/100 -> 0.48 | AC28: =Rich5!$K27/100 -> 0 | AD28: =Rich5!$G28/100 -> 0.97 | AI28: =Baserun3!$K27/100 -> 0 | AJ28: =Baserun3!$G28/100 -> 1 | AK28: =Baserun4!$K27/100 -> 0.02 | AL28: =Baserun4!$G28/100 -> 0.38 | AM28: =Baserun5!$K27/100 -> 0 | AN28: =Baserun5!$G28/100 -> 0.96 | AO28: =A28 -> 0 | AP28: =B28 -> 0.99 | AQ28: =K28 -> 0.04 | AR28: =L28 -> 0.16 | AS28: =W6 -> 0.02 | AT28: =X6 -> 0.54 | AU28: =AG6 -> 0.02 | AV28: =AH6 -> 0.37
A29: =Aware1!$K28/100 -> 0 | B29: =Aware1!$G29/100 -> 1 | C29: =Aware2!$K28/100 -> 0.01 | D29: =Aware2!$G29/100 -> 0.59 | E29: =Aware3!$K28/100 -> 0 | F29: =Aware3!$G29/100 -> 0.96 | G29: =Aware4!$K28/100 -> 0.01 | H29: =Aware4!$G29/100 -> 0.58 | K29: =Learn1!$K28/100 -> 0 | L29: =Learn1!$G29/100 -> 0.95 | M29: =Learn2!$K28/100 -> 0 | N29: =Learn2!$G29/100 -> 1 | O29: =Learn3!$K28/100 -> 0 | P29: =Learn3!$G29/100 -> 0.99 | Q29: =Learn4!$K28/100 -> 0.02 | R29: =Learn4!$G29/100 -> 0.14 | S29: =Learn5!$K28/100 -> 0 | T29: =Learn5!$G29/100 -> 0.96 | W29: =Rich2!$K28/100 -> 0 | X29: =Rich2!$G29/100 -> 0.95 | Y29: =Rich3!$K28/100 -> 0.01 | Z29: =Rich3!$G29/100 -> 0.67 | AA29: =Rich4!$K28/100 -> 0.03 | AB29: =Rich4!$G29/100 -> 0.44 | AC29: =Rich5!$K28/100 -> 0.01 | AD29: =Rich5!$G29/100 -> 0.67 | AI29: =Baserun3!$K28/100 -> 0.01 | AJ29: =Baserun3!$G29/100 -> 0.56 | AK29: =Baserun4!$K28/100 -> 0 | AL29: =Baserun4!$G29/100 -> 0.99 | AM29: =Baserun5!$K28/100 -> 0.04 | AN29: =Baserun5!$G29/100 -> 0.35 | AO29: =A29 -> 0 | AP29: =B29 -> 1 | AQ29: =K29 -> 0 | AR29: =L29 -> 0.95 | AS29: =W7 -> 0.01 | AT29: =X7 -> 0.79 | AU29: =AG7 -> 0.04 | AV29: =AH7 -> 0.36
A30: =Aware1!$K29/100 -> 0 | B30: =Aware1!$G30/100 -> 1 | C30: =Aware2!$K29/100 -> 0.02 | D30: =Aware2!$G30/100 -> 0.28 | E30: =Aware3!$K29/100 -> 0.02 | F30: =Aware3!$G30/100 -> 0.29 | G30: =Aware4!$K29/100 -> 0.02 | H30: =Aware4!$G30/100 -> 0.32 | K30: =Learn1!$K29/100 -> 0 | L30: =Learn1!$G30/100 -> 0.99 | M30: =Learn2!$K29/100 -> 0.01 | N30: =Learn2!$G30/100 -> 0.32 | O30: =Learn3!$K29/100 -> 0 | P30: =Learn3!$G30/100 -> 0.98 | Q30: =Learn4!$K29/100 -> 0.01 | R30: =Learn4!$G30/100 -> 0.2 | S30: =Learn5!$K29/100 -> 0 | T30: =Learn5!$G30/100 -> 0.98 | Y30: =Rich3!$K29/100 -> 0.01 | Z30: =Rich3!$G30/100 -> 0.72 | AA30: =Rich4!$K29/100 -> 0.02 | AB30: =Rich4!$G30/100 -> 0.49 | AC30: =Rich5!$K29/100 -> 0.01 | AD30: =Rich5!$G30/100 -> 0.67 | AI30: =Baserun3!$K29/100 -> 0.01 | AJ30: =Baserun3!$G30/100 -> 0.55 | AK30: =Baserun4!$K29/100 -> 0.01 | AL30: =Baserun4!$G30/100 -> 0.53 | AM30: =Baserun5!$K29/100 -> 0 | AN30: =Baserun5!$G30/100 -> 0.97 | AO30: =A30 -> 0 | AP30: =B30 -> 1 | AQ30: =K30 -> 0 | AR30: =L30 -> 0.99 | AS30: =W8 -> 0.02 | AT30: =X8 -> 0.51 | AU30: =AG8 -> 0.09 | AV30: =AH8 -> 0.28
A31: =Aware1!$K30/100 -> 0 | B31: =Aware1!$G31/100 -> 1 | C31: =Aware2!$K30/100 -> 0 | D31: =Aware2!$G31/100 -> 0.98 | E31: =Aware3!$K30/100 -> 0.04 | F31: =Aware3!$G31/100 -> 0.24 | G31: =Aware4!$K30/100 -> 0.02 | H31: =Aware4!$G31/100 -> 0.33 | K31: =Learn1!$K30/100 -> 0.02 | L31: =Learn1!$G31/100 -> 0.17 | M31: =Learn2!$K30/100 -> 0 | N31: =Learn2!$G31/100 -> 1 | O31: =Learn3!$K30/100 -> 0 | P31: =Learn3!$G31/100 -> 0.98 | Q31: =Learn4!$K30/100 -> 0.05 | R31: =Learn4!$G31/100 -> 0.08 | S31: =Learn5!$K30/100 -> 0.02 | T31: =Learn5!$G31/100 -> 0.19 | Y31: =Rich3!$K30/100 -> 0.01 | Z31: =Rich3!$G31/100 -> 0.7 | AA31: =Rich4!$K30/100 -> 0.05 | AB31: =Rich4!$G31/100 -> 0.47 | AC31: =Rich5!$K30/100 -> 0 | AD31: =Rich5!$G31/100 -> 0.95 | AI31: =Baserun3!$K30/100 -> 0.04 | AJ31: =Baserun3!$G31/100 -> 0.46 | AK31: =Baserun4!$K30/100 -> 0 | AL31: =Baserun4!$G31/100 -> 0.99 | AM31: =Baserun5!$K30/100 -> 0 | AN31: =Baserun5!$G31/100 -> 0.98 | AO31: =A31 -> 0 | AP31: =B31 -> 1 | AQ31: =K31 -> 0.02 | AR31: =L31 -> 0.17 | AS31: =W9 -> 0.04 | AT31: =X9 -> 0.49 | AU31: =AG9 -> 0.1 | AV31: =AH9 -> 0.14
A32: =Aware1!$K31/100 -> 0 | B32: =Aware1!$G32/100 -> 1 | C32: =Aware2!$K31/100 -> 0 | D32: =Aware2!$G32/100 -> 1 | E32: =Aware3!$K31/100 -> 0.02 | F32: =Aware3!$G32/100 -> 0.28 | G32: =Aware4!$K31/100 -> 0 | H32: =Aware4!$G32/100 -> 0.97 | K32: =Learn1!$K31/100 -> 0 | L32: =Learn1!$G32/100 -> 0.98 | M32: =Learn2!$K31/100 -> 0.01 | N32: =Learn2!$G32/100 -> 0.32 | O32: =Learn3!$K31/100 -> 0.01 | P32: =Learn3!$G32/100 -> 0.18 | Q32: =Learn4!$K31/100 -> 0 | R32: =Learn4!$G32/100 -> 0.94 | S32: =Learn5!$K31/100 -> 0 | T32: =Learn5!$G32/100 -> 0.97 | Y32: =Rich3!$K31/100 -> 0.01 | Z32: =Rich3!$G32/100 -> 0.66 | AA32: =Rich4!$K31/100 -> 0 | AB32: =Rich4!$G32/100 -> 0.94 | AC32: =Rich5!$K31/100 -> 0.01 | AD32: =Rich5!$G32/100 -> 0.68 | AI32: =Baserun3!$K31/100 -> 0.03 | AJ32: =Baserun3!$G32/100 -> 0.4 | AK32: =Baserun4!$K31/100 -> 0 | AL32: =Baserun4!$G32/100 -> 1 | AM32: =Baserun5!$K31/100 -> 0.02 | AN32: =Baserun5!$G32/100 -> 0.31 | AO32: =A32 -> 0 | AP32: =B32 -> 1 | AQ32: =K32 -> 0 | AR32: =L32 -> 0.98 | AS32: =W10 -> 0.05 | AT32: =X10 -> 0.51 | AU32: =AG10 -> 0.06 | AV32: =AH10 -> 0.26
A33: =Aware1!$K32/100 -> 0.01 | B33: =Aware1!$G33/100 -> 0.62 | C33: =Aware2!$K32/100 -> 0 | D33: =Aware2!$G33/100 -> 1 | E33: =Aware3!$K32/100 -> 0.05 | F33: =Aware3!$G33/100 -> 0.2 | G33: =Aware4!$K32/100 -> 0.01 | H33: =Aware4!$G33/100 -> 0.6 | K33: =Learn1!$K32/100 -> 0 | L33: =Learn1!$G33/100 -> 1 | M33: =Learn2!$K32/100 -> 0.02 | N33: =Learn2!$G33/100 -> 0.13 | O33: =Learn3!$K32/100 -> 0.02 | P33: =Learn3!$G33/100 -> 0.05 | Q33: =Learn4!$K32/100 -> 0 | R33: =Learn4!$G33/100 -> 0.98 | S33: =Learn5!$K32/100 -> 0.02 | T33: =Learn5!$G33/100 -> 0.2 | Y33: =Rich3!$K32/100 -> 0 | Z33: =Rich3!$G33/100 -> 0.95 | AA33: =Rich4!$K32/100 -> 0 | AB33: =Rich4!$G33/100 -> 0.94 | AC33: =Rich5!$K32/100 -> 0 | AD33: =Rich5!$G33/100 -> 0.98 | AI33: =Baserun3!$K32/100 -> 0 | AJ33: =Baserun3!$G33/100 -> 0.97 | AK33: =Baserun4!$K32/100 -> 0.01 | AL33: =Baserun4!$G33/100 -> 0.52 | AM33: =Baserun5!$K32/100 -> 0 | AN33: =Baserun5!$G33/100 -> 0.98 | AO33: =A33 -> 0.01 | AP33: =B33 -> 0.62 | AQ33: =K33 -> 0 | AR33: =L33 -> 1 | AS33: =W11 -> 0.07 | AT33: =X11 -> 0.35 | AU33: =AG11 -> 0.05 | AV33: =AH11 -> 0.18
A34: =Aware1!$K33/100 -> 0 | B34: =Aware1!$G34/100 -> 0.99 | C34: =Aware2!$K33/100 -> 0 | D34: =Aware2!$G34/100 -> 0.98 | E34: =Aware3!$K33/100 -> 0.01 | F34: =Aware3!$G34/100 -> 0.52 | G34: =Aware4!$K33/100 -> 0 | H34: =Aware4!$G34/100 -> 1 | K34: =Learn1!$K33/100 -> 0.05 | L34: =Learn1!$G34/100 -> 0.18 | M34: =Learn2!$K33/100 -> 0 | N34: =Learn2!$G34/100 -> 0.98 | O34: =Learn3!$K33/100 -> 0 | P34: =Learn3!$G34/100 -> 0.97 | Q34: =Learn4!$K33/100 -> 0 | R34: =Learn4!$G34/100 -> 0.98 | S34: =Learn5!$K33/100 -> 0.05 | T34: =Learn5!$G34/100 -> 0.18 | Y34: =Rich3!$K33/100 -> 0 | Z34: =Rich3!$G34/100 -> 0.95 | AA34: =Rich4!$K33/100 -> 0.01 | AB34: =Rich4!$G34/100 -> 0.66 | AC34: =Rich5!$K33/100 -> 0.01 | AD34: =Rich5!$G34/100 -> 0.67 | AI34: =Baserun3!$K33/100 -> 0 | AJ34: =Baserun3!$G34/100 -> 0.97 | AK34: =Baserun4!$K33/100 -> 0 | AL34: =Baserun4!$G34/100 -> 0.99 | AM34: =Baserun5!$K33/100 -> 0.02 | AN34: =Baserun5!$G34/100 -> 0.29 | AO34: =A34 -> 0 | AP34: =B34 -> 0.99 | AQ34: =K34 -> 0.05 | AR34: =L34 -> 0.18 | AS34: =W12 -> 0.08 | AT34: =X12 -> 0.39 | AU34: =AG12 -> 0.07 | AV34: =AH12 -> 0.27
A35: =Aware1!$K34/100 -> 0.01 | B35: =Aware1!$G35/100 -> 0.57 | C35: =Aware2!$K34/100 -> 0.02 | D35: =Aware2!$G35/100 -> 0.29 | E35: =Aware3!$K34/100 -> 0.01 | F35: =Aware3!$G35/100 -> 0.48 | G35: =Aware4!$K34/100 -> 0 | H35: =Aware4!$G35/100 -> 1 | K35: =Learn1!$K34/100 -> 0 | L35: =Learn1!$G35/100 -> 0.97 | M35: =Learn2!$K34/100 -> 0.01 | N35: =Learn2!$G35/100 -> 0.28 | O35: =Learn3!$K34/100 -> 0.01 | P35: =Learn3!$G35/100 -> 0.2 | Q35: =Learn4!$K34/100 -> 0 | R35: =Learn4!$G35/100 -> 0.98 | S35: =Learn5!$K34/100 -> 0 | T35: =Learn5!$G35/100 -> 0.93 | AA35: =Rich4!$K34/100 -> 0 | AB35: =Rich4!$G35/100 -> 0.98 | AC35: =Rich5!$K34/100 -> 0 | AD35: =Rich5!$G35/100 -> 0.98 | AK35: =Baserun4!$K34/100 -> 0 | AL35: =Baserun4!$G35/100 -> 0.99 | AM35: =Baserun5!$K34/100 -> 0.02 | AN35: =Baserun5!$G35/100 -> 0.29 | AO35: =A35 -> 0.01 | AP35: =B35 -> 0.57 | AQ35: =K35 -> 0 | AR35: =L35 -> 0.97 | AS35: =W13 -> 0.06 | AT35: =X13 -> 0.36 | AU35: =AG13 -> 0.02 | AV35: =AH13 -> 0.26
A36: =Aware1!$K35/100 -> 0.01 | B36: =Aware1!$G36/100 -> 0.55 | C36: =Aware2!$K35/100 -> 0.03 | D36: =Aware2!$G36/100 -> 0.34 | E36: =Aware3!$K35/100 -> 0 | F36: =Aware3!$G36/100 -> 0.98 | G36: =Aware4!$K35/100 -> 0.02 | H36: =Aware4!$G36/100 -> 0.31 | K36: =Learn1!$K35/100 -> 0.04 | L36: =Learn1!$G36/100 -> 0.15 | M36: =Learn2!$K35/100 -> 0 | N36: =Learn2!$G36/100 -> 0.99 | O36: =Learn3!$K35/100 -> 0 | P36: =Learn3!$G36/100 -> 0.97 | Q36: =Learn4!$K35/100 -> 0 | R36: =Learn4!$G36/100 -> 0.98 | S36: =Learn5!$K35/100 -> 0.02 | T36: =Learn5!$G36/100 -> 0.21 | AA36: =Rich4!$K35/100 -> 0 | AB36: =Rich4!$G36/100 -> 0.96 | AC36: =Rich5!$K35/100 -> 0 | AD36: =Rich5!$G36/100 -> 0.97 | AK36: =Baserun4!$K35/100 -> 0.01 | AL36: =Baserun4!$G36/100 -> 0.5 | AM36: =Baserun5!$K35/100 -> 0 | AN36: =Baserun5!$G36/100 -> 0.98 | AO36: =A36 -> 0.01 | AP36: =B36 -> 0.55 | AQ36: =K36 -> 0.04 | AR36: =L36 -> 0.15 | AS36: =W14 -> 0.11 | AT36: =X14 -> 0.36 | AU36: =AG14 -> 0.05 | AV36: =AH14 -> 0.23
A37: =Aware1!$K36/100 -> 0.03 | B37: =Aware1!$G37/100 -> 0.32 | C37: =Aware2!$K36/100 -> 0.03 | D37: =Aware2!$G37/100 -> 0.31 | E37: =Aware3!$K36/100 -> 0 | F37: =Aware3!$G37/100 -> 0.99 | G37: =Aware4!$K36/100 -> 0.01 | H37: =Aware4!$G37/100 -> 0.56 | K37: =Learn1!$K36/100 -> 0.06 | L37: =Learn1!$G37/100 -> 0.19 | M37: =Learn2!$K36/100 -> 0 | N37: =Learn2!$G37/100 -> 1 | O37: =Learn3!$K36/100 -> 0 | P37: =Learn3!$G37/100 -> 0.98 | Q37: =Learn4!$K36/100 -> 0.02 | R37: =Learn4!$G37/100 -> 0.14 | S37: =Learn5!$K36/100 -> 0 | T37: =Learn5!$G37/100 -> 0.96 | AA37: =Rich4!$K36/100 -> 0.02 | AB37: =Rich4!$G37/100 -> 0.5 | AK37: =Baserun4!$K36/100 -> 0 | AL37: =Baserun4!$G37/100 -> 0.99 | AM37: =Baserun5!$K36/100 -> 0.02 | AN37: =Baserun5!$G37/100 -> 0.3 | AO37: =A37 -> 0.03 | AP37: =B37 -> 0.32 | AQ37: =K37 -> 0.06 | AR37: =L37 -> 0.19 | AS37: =W15 -> 0.04 | AT37: =X15 -> 0.47 | AU37: =AG15 -> 0.04 | AV37: =AH15 -> 0.27
A38: =Aware1!$K37/100 -> 0.01 | B38: =Aware1!$G38/100 -> 0.58 | C38: =Aware2!$K37/100 -> 0.04 | D38: =Aware2!$G38/100 -> 0.32 | E38: =Aware3!$K37/100 -> 0.01 | F38: =Aware3!$G38/100 -> 0.49 | G38: =Aware4!$K37/100 -> 0.04 | H38: =Aware4!$G38/100 -> 0.25 | K38: =Learn1!$K37/100 -> 0 | L38: =Learn1!$G38/100 -> 0.93 | M38: =Learn2!$K37/100 -> 0.01 | N38: =Learn2!$G38/100 -> 0.3 | Q38: =Learn4!$K37/100 -> 0.01 | R38: =Learn4!$G38/100 -> 0.22 | S38: =Learn5!$K37/100 -> 0 | T38: =Learn5!$G38/100 -> 0.98 | AA38: =Rich4!$K37/100 -> 0 | AB38: =Rich4!$G38/100 -> 0.97 | AK38: =Baserun4!$K37/100 -> 0.01 | AL38: =Baserun4!$G38/100 -> 0.55 | AM38: =Baserun5!$K37/100 -> 0 | AN38: =Baserun5!$G38/100 -> 0.98 | AO38: =A38 -> 0.01 | AP38: =B38 -> 0.58 | AQ38: =K38 -> 0 | AR38: =L38 -> 0.93 | AS38: =W16 -> 0.08 | AT38: =X16 -> 0.45 | AU38: =AG16 -> 0.04 | AV38: =AH16 -> 0.29
A39: =Aware1!$K38/100 -> 0 | B39: =Aware1!$G39/100 -> 0.98 | C39: =Aware2!$K38/100 -> 0 | D39: =Aware2!$G39/100 -> 0.95 | E39: =Aware3!$K38/100 -> 0 | F39: =Aware3!$G39/100 -> 0.99 | G39: =Aware4!$K38/100 -> 0.03 | H39: =Aware4!$G39/100 -> 0.29 | K39: =Learn1!$K38/100 -> 0.01 | L39: =Learn1!$G39/100 -> 0.26 | M39: =Learn2!$K38/100 -> 0 | N39: =Learn2!$G39/100 -> 0.99 | Q39: =Learn4!$K38/100 -> 0 | R39: =Learn4!$G39/100 -> 0.98 | S39: =Learn5!$K38/100 -> 0.04 | T39: =Learn5!$G39/100 -> 0.24 | AA39: =Rich4!$K38/100 -> 0 | AB39: =Rich4!$G39/100 -> 0.96 | AK39: =Baserun4!$K38/100 -> 0 | AL39: =Baserun4!$G39/100 -> 0.99 | AM39: =Baserun5!$K38/100 -> 0 | AN39: =Baserun5!$G39/100 -> 0.99 | AO39: =A39 -> 0 | AP39: =B39 -> 0.98 | AQ39: =K39 -> 0.01 | AR39: =L39 -> 0.26 | AS39: =W17 -> 0.06 | AT39: =X17 -> 0.46 | AU39: =AG17 -> 0 | AV39: =AH17 -> 0.95
A40: =Aware1!$K39/100 -> 0 | B40: =Aware1!$G40/100 -> 1 | C40: =Aware2!$K39/100 -> 0 | D40: =Aware2!$G40/100 -> 0.98 | E40: =Aware3!$K39/100 -> 0 | F40: =Aware3!$G40/100 -> 1 | G40: =Aware4!$K39/100 -> 0 | H40: =Aware4!$G40/100 -> 0.97 | K40: =Learn1!$K39/100 -> 0 | L40: =Learn1!$G40/100 -> 0.99 | M40: =Learn2!$K39/100 -> 0 | N40: =Learn2!$G40/100 -> 1 | Q40: =Learn4!$K39/100 -> 0.02 | R40: =Learn4!$G40/100 -> 0.15 | S40: =Learn5!$K39/100 -> 0 | T40: =Learn5!$G40/100 -> 0.96 | AK40: =Baserun4!$K39/100 -> 0 | AL40: =Baserun4!$G40/100 -> 1 | AM40: =Baserun5!$K39/100 -> 0.03 | AN40: =Baserun5!$G40/100 -> 0.42 | AO40: =A40 -> 0 | AP40: =B40 -> 1 | AQ40: =K40 -> 0 | AR40: =L40 -> 0.99 | AS40: =W18 -> 0.01 | AT40: =X18 -> 0.7 | AU40: =AG18 -> 0.01 | AV40: =AH18 -> 0.44
A41: =Aware1!$K40/100 -> 0 | B41: =Aware1!$G41/100 -> 1 | C41: =Aware2!$K40/100 -> 0 | D41: =Aware2!$G41/100 -> 1 | E41: =Aware3!$K40/100 -> 0 | F41: =Aware3!$G41/100 -> 1 | G41: =Aware4!$K40/100 -> 0 | H41: =Aware4!$G41/100 -> 1 | K41: =Learn1!$K40/100 -> 0 | L41: =Learn1!$G41/100 -> 0.99 | M41: =Learn2!$K40/100 -> 0.02 | N41: =Learn2!$G41/100 -> 0.11 | Q41: =Learn4!$K40/100 -> 0 | R41: =Learn4!$G41/100 -> 0.97 | S41: =Learn5!$K40/100 -> 0.01 | T41: =Learn5!$G41/100 -> 0.23 | AK41: =Baserun4!$K40/100 -> 0 | AL41: =Baserun4!$G41/100 -> 1 | AM41: =Baserun5!$K40/100 -> 0 | AN41: =Baserun5!$G41/100 -> 0.97 | AO41: =A41 -> 0 | AP41: =B41 -> 1 | AQ41: =K41 -> 0 | AR41: =L41 -> 0.99 | AS41: =W19 -> 0.04 | AT41: =X19 -> 0.44 | AU41: =AG19 -> 0 | AV41: =AH19 -> 0.99
A42: =Aware1!$K41/100 -> 0 | B42: =Aware1!$G42/100 -> 0.99 | C42: =Aware2!$K41/100 -> 0 | D42: =Aware2!$G42/100 -> 1 | E42: =Aware3!$K41/100 -> 0 | F42: =Aware3!$G42/100 -> 1 | G42: =Aware4!$K41/100 -> 0 | H42: =Aware4!$G42/100 -> 1 | K42: =Learn1!$K41/100 -> 0.06 | L42: =Learn1!$G42/100 -> 0.17 | M42: =Learn2!$K41/100 -> 0 | N42: =Learn2!$G42/100 -> 0.99 | Q42: =Learn4!$K41/100 -> 0 | R42: =Learn4!$G42/100 -> 0.99 | S42: =Learn5!$K41/100 -> 0.04 | T42: =Learn5!$G42/100 -> 0.21 | AK42: =Baserun4!$K41/100 -> 0.01 | AL42: =Baserun4!$G42/100 -> 0.5 | AM42: =Baserun5!$K41/100 -> 0.01 | AN42: =Baserun5!$G42/100 -> 0.45 | AO42: =A42 -> 0 | AP42: =B42 -> 0.99 | AQ42: =K42 -> 0.06 | AR42: =L42 -> 0.17 | AS42: =W20 -> 0.01 | AT42: =X20 -> 0.72 | AU42: =AG20 -> 0 | AV42: =AH20 -> 0.99
A43: =Aware1!$K42/100 -> 0.02 | B43: =Aware1!$G43/100 -> 0.36 | C43: =Aware2!$K42/100 -> 0.01 | D43: =Aware2!$G43/100 -> 0.62 | E43: =Aware3!$K42/100 -> 0 | F43: =Aware3!$G43/100 -> 1 | G43: =Aware4!$K42/100 -> 0 | H43: =Aware4!$G43/100 -> 0.98 | K43: =Learn1!$K42/100 -> 0 | L43: =Learn1!$G43/100 -> 0.95 | M43: =Learn2!$K42/100 -> 0 | N43: =Learn2!$G43/100 -> 1 | S43: =Learn5!$K42/100 -> 0 | T43: =Learn5!$G43/100 -> 0.94 | AK43: =Baserun4!$K42/100 -> 0.01 | AL43: =Baserun4!$G43/100 -> 0.51 | AM43: =Baserun5!$K42/100 -> 0.01 | AN43: =Baserun5!$G43/100 -> 0.43 | AO43: =A43 -> 0.02 | AP43: =B43 -> 0.36 | AQ43: =K43 -> 0 | AR43: =L43 -> 0.95 | AS43: =W21 -> 0 | AT43: =X21 -> 0.97 | AU43: =AG21 -> 0.01 | AV43: =AH21 -> 0.48
A44: =Aware1!$K43/100 -> 0.01 | B44: =Aware1!$G44/100 -> 0.59 | C44: =Aware2!$K43/100 -> 0.01 | D44: =Aware2!$G44/100 -> 0.6 | E44: =Aware3!$K43/100 -> 0.01 | F44: =Aware3!$G44/100 -> 0.49 | G44: =Aware4!$K43/100 -> 0.03 | H44: =Aware4!$G44/100 -> 0.32 | K44: =Learn1!$K43/100 -> 0.02 | L44: =Learn1!$G44/100 -> 0.17 | M44: =Learn2!$K43/100 -> 0.01 | N44: =Learn2!$G44/100 -> 0.28 | S44: =Learn5!$K43/100 -> 0.04 | T44: =Learn5!$G44/100 -> 0.22 | AK44: =Baserun4!$K43/100 -> 0.01 | AL44: =Baserun4!$G44/100 -> 0.5 | AM44: =Baserun5!$K43/100 -> 0.01 | AN44: =Baserun5!$G44/100 -> 0.48 | AO44: =A44 -> 0.01 | AP44: =B44 -> 0.59 | AQ44: =K44 -> 0.02 | AR44: =L44 -> 0.17 | AS44: =W22 -> 0.03 | AT44: =X22 -> 0.5 | AU44: =AG22 -> 0 | AV44: =AH22 -> 0.99
A45: =Aware1!$K44/100 -> 0.02 | B45: =Aware1!$G45/100 -> 0.35 | C45: =Aware2!$K44/100 -> 0 | D45: =Aware2!$G45/100 -> 1 | E45: =Aware3!$K44/100 -> 0 | F45: =Aware3!$G45/100 -> 1 | G45: =Aware4!$K44/100 -> 0.05 | H45: =Aware4!$G45/100 -> 0.31 | K45: =Learn1!$K44/100 -> 0.03 | L45: =Learn1!$G45/100 -> 0.17 | M45: =Learn2!$K44/100 -> 0 | N45: =Learn2!$G45/100 -> 0.99 | S45: =Learn5!$K44/100 -> 0 | T45: =Learn5!$G45/100 -> 0.94 | AK45: =Baserun4!$K44/100 -> 0 | AL45: =Baserun4!$G45/100 -> 1 | AM45: =Baserun5!$K44/100 -> 0.01 | AN45: =Baserun5!$G45/100 -> 0.49 | AO45: =A45 -> 0.02 | AP45: =B45 -> 0.35 | AQ45: =K45 -> 0.03 | AR45: =L45 -> 0.17 | AS45: =W23 -> 0 | AT45: =X23 -> 0.96 | AU45: =AG23 -> 0 | AV45: =AH23 -> 0.99
A46: =Aware1!$K45/100 -> 0.01 | B46: =Aware1!$G46/100 -> 0.57 | C46: =Aware2!$K45/100 -> 0.01 | D46: =Aware2!$G46/100 -> 0.62 | E46: =Aware3!$K45/100 -> 0 | F46: =Aware3!$G46/100 -> 1 | G46: =Aware4!$K45/100 -> 0.04 | H46: =Aware4!$G46/100 -> 0.26 | K46: =Learn1!$K45/100 -> 0 | L46: =Learn1!$G46/100 -> 0.98 | M46: =Learn2!$K45/100 -> 0.02 | N46: =Learn2!$G46/100 -> 0.12 | S46: =Learn5!$K45/100 -> 0 | T46: =Learn5!$G46/100 -> 0.98 | AK46: =Baserun4!$K45/100 -> 0 | AL46: =Baserun4!$G46/100 -> 1 | AM46: =Baserun5!$K45/100 -> 0 | AN46: =Baserun5!$G46/100 -> 0.98 | AO46: =A46 -> 0.01 | AP46: =B46 -> 0.57 | AQ46: =K46 -> 0 | AR46: =L46 -> 0.98 | AS46: =W24 -> 0.01 | AT46: =X24 -> 0.72 | AU46: =AI3 -> 0 | AV46: =AJ3 -> 1
A47: =Aware1!$K46/100 -> 0.02 | B47: =Aware1!$G47/100 -> 0.32 | C47: =Aware2!$K46/100 -> 0 | D47: =Aware2!$G47/100 -> 1 | E47: =Aware3!$K46/100 -> 0.01 | F47: =Aware3!$G47/100 -> 0.51 | G47: =Aware4!$K46/100 -> 0.03 | H47: =Aware4!$G47/100 -> 0.33 | K47: =Learn1!$K46/100 -> 0.02 | L47: =Learn1!$G47/100 -> 0.17 | M47: =Learn2!$K46/100 -> 0.03 | N47: =Learn2!$G47/100 -> 0.18 | AM47: =Baserun5!$K46/100 -> 0 | AN47: =Baserun5!$G47/100 -> 0.99 | AO47: =A47 -> 0.02 | AP47: =B47 -> 0.32 | AQ47: =K47 -> 0.02 | AR47: =L47 -> 0.17 | AS47: =W25 -> 0.01 | AT47: =X25 -> 0.76 | AU47: =AI4 -> 0 | AV47: =AJ4 -> 1
A48: =Aware1!$K47/100 -> 0.01 | B48: =Aware1!$G48/100 -> 0.58 | C48: =Aware2!$K47/100 -> 0 | D48: =Aware2!$G48/100 -> 1 | E48: =Aware3!$K47/100 -> 0 | F48: =Aware3!$G48/100 -> 1 | G48: =Aware4!$K47/100 -> 0 | H48: =Aware4!$G48/100 -> 0.93 | K48: =Learn1!$K47/100 -> 0 | L48: =Learn1!$G48/100 -> 0.99 | M48: =Learn2!$K47/100 -> 0 | N48: =Learn2!$G48/100 -> 0.99 | AO48: =A48 -> 0.01 | AP48: =B48 -> 0.58 | AQ48: =K48 -> 0 | AR48: =L48 -> 0.99 | AS48: =W26 -> 0 | AT48: =X26 -> 0.95 | AU48: =AI5 -> 0 | AV48: =AJ5 -> 0.99
...

Sheet Full data
A1: infec | G1: mob | N1: Infected | T1: Mobility (6 Day Average)
B2: Know | C2: Aware | D2: Learn | E2: Savings | H2: Know | I2: Aware | J2: Learn | K2: Savings | N2: Baserun | O2: Aware of | P2: Learn | Q2: Rich | T2: Baserun | U2: Aware of | V2: Learn | W2: Rich
A3: Cummulative (50ts) | B3: =Baserun_Full!H53 -> 65.2 | C3: =Aware_Full!H53 -> 66.2 | D3: =Learn_Full!H53 -> 67.6 | E3: =Rich_Full!H53 -> 79.8 | G3: Cummulative (50ts) | H3: =Baserun_Full!R53 -> 3683.8 | I3: =Aware_Full!R53 -> 3418.6 | J3: =Learn_Full!R53 -> 3109 | K3: =Rich_Full!R53 -> 3894.2 | M3: Cummulative (50ts) | N3: =Baserun_Full!AB53 -> 391.2 | O3: =Aware_Full!AB53 -> 395.8 | P3: =Learn_Full!AB53 -> 398 | Q3: =Rich_Full!AB53 -> 478.8 | S3: Cummulative (50ts) | T3: =Baserun_Full!AL53 -> 3681.4333 | U3: =Aware_Full!AL53 -> 3437.7633 | V3: =Learn_Full!AL53 -> 3127.9267 | W3: =Rich_Full!AL53 -> 3889.73
A4: Average per ts | B4: =Baserun_Full!H55 -> 2.0114771 | C4: =Aware_Full!H55 -> 1.4913475 | D4: =Learn_Full!H55 -> 1.5041734 | E4: =Rich_Full!H55 -> 2.5364066 | G4: Average per ts | H4: =Baserun_Full!R55 -> 60.179293 | I4: =Aware_Full!R55 -> 64.015033 | J4: =Learn_Full!R55 -> 56.654702 | K4: =Rich_Full!R55 -> 63.97528 | M4: Average per ts | N4: =Baserun_Full!AB55 -> 12.068863 | O4: =Aware_Full!AB55 -> 8.9147518 | P4: =Learn_Full!AB55 -> 8.798374 | Q4: =Rich_Full!AB55 -> 15.21844 | S4: Average per ts | T4: =Baserun_Full!AL55 -> 61.633406 | U4: =Aware_Full!AL55 -> 64.775972 | V4: =Learn_Full!AL55 -> 57.903727 | W4: =Rich_Full!AL55 -> 65.107622
P6: I am dumb… Idk why I got this data for bar charts lol
A7: Cummulative (%) | B7: =B3/100*100 -> 65.2 | C7: =C3/100*100 -> 66.2 | D7: =D3/100*100 -> 67.6 | E7: =E3/100*100 -> 79.8 | G7: Cummulative (%) | H7: =H3/5000*100 -> 73.676 | I7: =I3/5000*100 -> 68.372 | J7: =J3/5000*100 -> 62.18 | K7: =K3/5000*100 -> 77.884

Sheet Full data mobility detail
A1: Mobility | AA1: Mobility 6 Day Average
B2: Base run | G2: Aware of | L2: Learn | Q2: Rich | AB2: Base run | AG2: Aware of | AL2: Learn | AQ2: Rich
A3: =Baserun_Full!A2 -> Time | B3: =Baserun_Full!B2 -> NI_Baserun1 | C3: =Baserun_Full!C2 -> NI_Baserun2 | D3: =Baserun_Full!D2 -> NI_Baserun3 | E3: =Baserun_Full!E2 -> NI_Baserun4 | F3: =Baserun_Full!F2 -> NI_Baserun5 | G3: =Aware_Full!B2 -> NI_Aware1 | H3: =Aware_Full!C2 -> NI_Aware2 | I3: =Aware_Full!D2 -> NI_Aware3 | J3: =Aware_Full!E2 -> NI_Aware4 | K3: =Aware_Full!F2 -> NI_Aware5 | L3: =Learn_Full!B2 -> NI_Learn1 | M3: =Learn_Full!C2 -> NI_Learn2 | N3: =Learn_Full!D2 -> NI_Learn3 | O3: =Learn_Full!E2 -> NI_Learn4 | P3: =Learn_Full!F2 -> NI_Learn5 | Q3: =Rich_Full!B2 -> NI_Rich1 | R3: =Rich_Full!C2 -> NI_Rich2 | S3: =Rich_Full!D2 -> NI_Rich3 | T3: =Rich_Full!E2 -> NI_Rich4 | U3: =Rich_Full!F2 -> NI_Rich5 | W3: Min | X3: Average | Y3: Max | AA3: =Baserun_Full!AE2 -> Time | AB3: =Baserun_Full!AF2 -> Mob6_Baserun1 | AC3: =Baserun_Full!AG2 -> Mob6_Baserun2 | AD3: =Baserun_Full!AH2 -> Mob6_Baserun3 | AE3: =Baserun_Full!AI2 -> Mob6_Baserun4 | AF3: =Baserun_Full!AJ2 -> Mob6_Baserun5 | AG3: =Aware_Full!AF2 -> Mob6_Aware1 | AH3: =Aware_Full!AG2 -> Mob6_Aware2 | AI3: =Aware_Full!AH2 -> Mob6_Aware3 | AJ3: =Aware_Full!AI2 -> Mob6_Aware4 | AK3: =Aware_Full!AJ2 -> Mob6_Aware5 | AL3: =Learn_Full!AF2 -> Mob6_Learn1 | AM3: =Learn_Full!AG2 -> Mob6_Learn2 | AN3: =Learn_Full!AH2 -> Mob6_Learn3 | AO3: =Learn_Full!AI2 -> Mob6_Learn4 | AP3: =Learn_Full!AJ2 -> Mob6_Learn5 | AQ3: =Rich_Full!AF2 -> Mob6_Rich1 | AR3: =Rich_Full!AG2 -> Mob6_Rich2 | AS3: =Rich_Full!AH2 -> Mob6_Rich3 | AT3: =Rich_Full!AI2 -> Mob6_Rich4 | AU3: =Rich_Full!AJ2 -> Mob6_Rich5 | AW3: 25th | AX3: 50th | AY3: 75th
A4: =Baserun_Full!A3 -> 0 | B4: =Baserun_Full!L3 -> 100 | C4: =Baserun_Full!M3 -> 100 | D4: =Baserun_Full!N3 -> 100 | E4: =Baserun_Full!O3 -> 100 | F4: =Baserun_Full!P3 -> 100 | G4: =Aware_Full!L3 -> 100 | H4: =Aware_Full!M3 -> 100 | I4: =Aware_Full!N3 -> 100 | J4: =Aware_Full!O3 -> 100 | K4: =Aware_Full!P3 -> 100 | L4: =Learn_Full!L3 -> 100 | M4: =Learn_Full!M3 -> 100 | N4: =Learn_Full!N3 -> 100 | O4: =Learn_Full!O3 -> 100 | P4: =Learn_Full!P3 -> 100 | Q4: =Rich_Full!L3 -> 100 | R4: =Rich_Full!M3 -> 100 | S4: =Rich_Full!N3 -> 100 | T4: =Rich_Full!O3 -> 100 | U4: =Rich_Full!P3 -> 100 | W4: =PERCENTILE(B4:P4,0.25) -> 100 | X4: =PERCENTILE(B4:P4,0.5) -> 100 | Y4: =PERCENTILE(B4:P4,0.75) -> 100 | AA4: =Baserun_Full!AE3 -> 0 | AB4: =Baserun_Full!AF3 -> 100 | AC4: =Baserun_Full!AG3 -> 100 | AD4: =Baserun_Full!AH3 -> 100 | AE4: =Baserun_Full!AI3 -> 100 | AF4: =Baserun_Full!AJ3 -> 100 | AG4: =Aware_Full!AF3 -> 100 | AH4: =Aware_Full!AG3 -> 100 | AI4: =Aware_Full!AH3 -> 100 | AJ4: =Aware_Full!AI3 -> 100 | AK4: =Aware_Full!AJ3 -> 100 | AL4: =Learn_Full!AF3 -> 100 | AM4: =Learn_Full!AG3 -> 100 | AN4: =Learn_Full!AH3 -> 100 | AO4: =Learn_Full!AI3 -> 100 | AP4: =Learn_Full!AJ3 -> 100 | AQ4: =Rich_Full!AF3 -> 100 | AR4: =Rich_Full!AG3 -> 100 | AS4: =Rich_Full!AH3 -> 100 | AT4: =Rich_Full!AI3 -> 100 | AU4: =Rich_Full!AJ3 -> 100 | AW4: =PERCENTILE(AB4:AP4,0.25)/100 -> 1 | AX4: =PERCENTILE(AB4:AP4,0.5)/100 -> 1 | AY4: =PERCENTILE(AB4:AP4,0.75)/100 -> 1
A5: =Baserun_Full!A4 -> 1 | B5: =Baserun_Full!L4 -> 100 | C5: =Baserun_Full!M4 -> 100 | D5: =Baserun_Full!N4 -> 100 | E5: =Baserun_Full!O4 -> 100 | F5: =Baserun_Full!P4 -> 99 | G5: =Aware_Full!L4 -> 100 | H5: =Aware_Full!M4 -> 100 | I5: =Aware_Full!N4 -> 100 | J5: =Aware_Full!O4 -> 100 | K5: =Aware_Full!P4 -> 100 | L5: =Learn_Full!L4 -> 100 | M5: =Learn_Full!M4 -> 100 | N5: =Learn_Full!N4 -> 98 | O5: =Learn_Full!O4 -> 98 | P5: =Learn_Full!P4 -> 98 | Q5: =Rich_Full!L4 -> 99 | R5: =Rich_Full!M4 -> 98 | S5: =Rich_Full!N4 -> 95 | T5: =Rich_Full!O4 -> 98 | U5: =Rich_Full!P4 -> 98 | W5: =PERCENTILE(B5:P5,0.25) -> 99.5 | X5: =PERCENTILE(B5:P5,0.5) -> 100 | Y5: =PERCENTILE(B5:P5,0.75) -> 100 | AA5: =Baserun_Full!AE4 -> 1 | AB5: =Baserun_Full!AF4 -> 100 | AC5: =Baserun_Full!AG4 -> 100 | AD5: =Baserun_Full!AH4 -> 100 | AE5: =Baserun_Full!AI4 -> 100 | AF5: =Baserun_Full!AJ4 -> 99.5 | AG5: =Aware_Full!AF4 -> 100 | AH5: =Aware_Full!AG4 -> 100 | AI5: =Aware_Full!AH4 -> 100 | AJ5: =Aware_Full!AI4 -> 100 | AK5: =Aware_Full!AJ4 -> 100 | AL5: =Learn_Full!AF4 -> 100 | AM5: =Learn_Full!AG4 -> 100 | AN5: =Learn_Full!AH4 -> 99 | AO5: =Learn_Full!AI4 -> 99 | AP5: =Learn_Full!AJ4 -> 99 | AQ5: =Rich_Full!AF4 -> 99.5 | AR5: =Rich_Full!AG4 -> 99 | AS5: =Rich_Full!AH4 -> 97.5 | AT5: =Rich_Full!AI4 -> 99 | AU5: =Rich_Full!AJ4 -> 99 | AW5: =PERCENTILE(AB5:AP5,0.25)/100 -> 0.9975 | AX5: =PERCENTILE(AB5:AP5,0.5)/100 -> 1 | AY5: =PERCENTILE(AB5:AP5,0.75)/100 -> 1
A6: =Baserun_Full!A5 -> 2 | B6: =Baserun_Full!L5 -> 100 | C6: =Baserun_Full!M5 -> 100 | D6: =Baserun_Full!N5 -> 100 | E6: =Baserun_Full!O5 -> 100 | F6: =Baserun_Full!P5 -> 99 | G6: =Aware_Full!L5 -> 100 | H6: =Aware_Full!M5 -> 100 | I6: =Aware_Full!N5 -> 100 | J6: =Aware_Full!O5 -> 100 | K6: =Aware_Full!P5 -> 100 | L6: =Learn_Full!L5 -> 99 | M6: =Learn_Full!M5 -> 100 | N6: =Learn_Full!N5 -> 98 | O6: =Learn_Full!O5 -> 98 | P6: =Learn_Full!P5 -> 98 | Q6: =Rich_Full!L5 -> 99 | R6: =Rich_Full!M5 -> 97 | S6: =Rich_Full!N5 -> 95 | T6: =Rich_Full!O5 -> 95 | U6: =Rich_Full!P5 -> 98 | W6: =PERCENTILE(B6:P6,0.25) -> 99 | X6: =PERCENTILE(B6:P6,0.5) -> 100 | Y6: =PERCENTILE(B6:P6,0.75) -> 100 | AA6: =Baserun_Full!AE5 -> 2 | AB6: =Baserun_Full!AF5 -> 100 | AC6: =Baserun_Full!AG5 -> 100 | AD6: =Baserun_Full!AH5 -> 100 | AE6: =Baserun_Full!AI5 -> 100 | AF6: =Baserun_Full!AJ5 -> 99.333333 | AG6: =Aware_Full!AF5 -> 100 | AH6: =Aware_Full!AG5 -> 100 | AI6: =Aware_Full!AH5 -> 100 | AJ6: =Aware_Full!AI5 -> 100 | AK6: =Aware_Full!AJ5 -> 100 | AL6: =Learn_Full!AF5 -> 99.666667 | AM6: =Learn_Full!AG5 -> 100 | AN6: =Learn_Full!AH5 -> 98.666667 | AO6: =Learn_Full!AI5 -> 98.666667 | AP6: =Learn_Full!AJ5 -> 98.666667 | AQ6: =Rich_Full!AF5 -> 99.333333 | AR6: =Rich_Full!AG5 -> 98.333333 | AS6: =Rich_Full!AH5 -> 96.666667 | AT6: =Rich_Full!AI5 -> 97.666667 | AU6: =Rich_Full!AJ5 -> 98.666667 | AW6: =PERCENTILE(AB6:AP6,0.25)/100 -> 0.995 | AX6: =PERCENTILE(AB6:AP6,0.5)/100 -> 1 | AY6: =PERCENTILE(AB6:AP6,0.75)/100 -> 1
A7: =Baserun_Full!A6 -> 3 | B7: =Baserun_Full!L6 -> 100 | C7: =Baserun_Full!M6 -> 99 | D7: =Baserun_Full!N6 -> 99 | E7: =Baserun_Full!O6 -> 99 | F7: =Baserun_Full!P6 -> 99 | G7: =Aware_Full!L6 -> 100 | H7: =Aware_Full!M6 -> 99 | I7: =Aware_Full!N6 -> 99 | J7: =Aware_Full!O6 -> 99 | K7: =Aware_Full!P6 -> 100 | L7: =Learn_Full!L6 -> 100 | M7: =Learn_Full!M6 -> 100 | N7: =Learn_Full!N6 -> 98 | O7: =Learn_Full!O6 -> 97 | P7: =Learn_Full!P6 -> 98 | Q7: =Rich_Full!L6 -> 97 | R7: =Rich_Full!M6 -> 97 | S7: =Rich_Full!N6 -> 95 | T7: =Rich_Full!O6 -> 98 | U7: =Rich_Full!P6 -> 96 | W7: =PERCENTILE(B7:P7,0.25) -> 99 | X7: =PERCENTILE(B7:P7,0.5) -> 99 | Y7: =PERCENTILE(B7:P7,0.75) -> 100 | AA7: =Baserun_Full!AE6 -> 3 | AB7: =Baserun_Full!AF6 -> 100 | AC7: =Baserun_Full!AG6 -> 99.75 | AD7: =Baserun_Full!AH6 -> 99.75 | AE7: =Baserun_Full!AI6 -> 99.75 | AF7: =Baserun_Full!AJ6 -> 99.25 | AG7: =Aware_Full!AF6 -> 100 | AH7: =Aware_Full!AG6 -> 99.75 | AI7: =Aware_Full!AH6 -> 99.75 | AJ7: =Aware_Full!AI6 -> 99.75 | AK7: =Aware_Full!AJ6 -> 100 | AL7: =Learn_Full!AF6 -> 99.75 | AM7: =Learn_Full!AG6 -> 100 | AN7: =Learn_Full!AH6 -> 98.5 | AO7: =Learn_Full!AI6 -> 98.25 | AP7: =Learn_Full!AJ6 -> 98.5 | AQ7: =Rich_Full!AF6 -> 98.75 | AR7: =Rich_Full!AG6 -> 98 | AS7: =Rich_Full!AH6 -> 96.25 | AT7: =Rich_Full!AI6 -> 97.75 | AU7: =Rich_Full!AJ6 -> 98 | AW7: =PERCENTILE(AB7:AP7,0.25)/100 -> 0.995 | AX7: =PERCENTILE(AB7:AP7,0.5)/100 -> 0.9975 | AY7: =PERCENTILE(AB7:AP7,0.75)/100 -> 0.99875
A8: =Baserun_Full!A7 -> 4 | B8: =Baserun_Full!L7 -> 39 | C8: =Baserun_Full!M7 -> 37 | D8: =Baserun_Full!N7 -> 38 | E8: =Baserun_Full!O7 -> 37 | F8: =Baserun_Full!P7 -> 30 | G8: =Aware_Full!L7 -> 34 | H8: =Aware_Full!M7 -> 27 | I8: =Aware_Full!N7 -> 28 | J8: =Aware_Full!O7 -> 32 | K8: =Aware_Full!P7 -> 34 | L8: =Learn_Full!L7 -> 19 | M8: =Learn_Full!M7 -> 11 | N8: =Learn_Full!N7 -> 5 | O8: =Learn_Full!O7 -> 14 | P8: =Learn_Full!P7 -> 20 | Q8: =Rich_Full!L7 -> 50 | R8: =Rich_Full!M7 -> 54 | S8: =Rich_Full!N7 -> 54 | T8: =Rich_Full!O7 -> 48 | U8: =Rich_Full!P7 -> 41 | W8: =PERCENTILE(B8:P8,0.25) -> 19.5 | X8: =PERCENTILE(B8:P8,0.5) -> 30 | Y8: =PERCENTILE(B8:P8,0.75) -> 35.5 | AA8: =Baserun_Full!AE7 -> 4 | AB8: =Baserun_Full!AF7 -> 87.8 | AC8: =Baserun_Full!AG7 -> 87.2 | AD8: =Baserun_Full!AH7 -> 87.4 | AE8: =Baserun_Full!AI7 -> 87.2 | AF8: =Baserun_Full!AJ7 -> 85.4 | AG8: =Aware_Full!AF7 -> 86.8 | AH8: =Aware_Full!AG7 -> 85.2 | AI8: =Aware_Full!AH7 -> 85.4 | AJ8: =Aware_Full!AI7 -> 86.2 | AK8: =Aware_Full!AJ7 -> 86.8 | AL8: =Learn_Full!AF7 -> 83.6 | AM8: =Learn_Full!AG7 -> 82.2 | AN8: =Learn_Full!AH7 -> 79.8 | AO8: =Learn_Full!AI7 -> 81.4 | AP8: =Learn_Full!AJ7 -> 82.8 | AQ8: =Rich_Full!AF7 -> 89 | AR8: =Rich_Full!AG7 -> 89.2 | AS8: =Rich_Full!AH7 -> 87.8 | AT8: =Rich_Full!AI7 -> 87.8 | AU8: =Rich_Full!AJ7 -> 86.6 | AW8: =PERCENTILE(AB8:AP8,0.25)/100 -> 0.832 | AX8: =PERCENTILE(AB8:AP8,0.5)/100 -> 0.854 | AY8: =PERCENTILE(AB8:AP8,0.75)/100 -> 0.87
A9: =Baserun_Full!A8 -> 5 | B9: =Baserun_Full!L8 -> 97 | C9: =Baserun_Full!M8 -> 36 | D9: =Baserun_Full!N8 -> 52 | E9: =Baserun_Full!O8 -> 42 | F9: =Baserun_Full!P8 -> 46 | G9: =Aware_Full!L8 -> 33 | H9: =Aware_Full!M8 -> 98 | I9: =Aware_Full!N8 -> 98 | J9: =Aware_Full!O8 -> 28 | K9: =Aware_Full!P8 -> 34 | L9: =Learn_Full!L8 -> 98 | M9: =Learn_Full!M8 -> 98 | N9: =Learn_Full!N8 -> 17 | O9: =Learn_Full!O8 -> 14 | P9: =Learn_Full!P8 -> 26 | Q9: =Rich_Full!L8 -> 45 | R9: =Rich_Full!M8 -> 79 | S9: =Rich_Full!N8 -> 49 | T9: =Rich_Full!O8 -> 42 | U9: =Rich_Full!P8 -> 41 | W9: =PERCENTILE(B9:P9,0.25) -> 30.5 | X9: =PERCENTILE(B9:P9,0.5) -> 42 | Y9: =PERCENTILE(B9:P9,0.75) -> 97.5 | AA9: =Baserun_Full!AE8 -> 5 | AB9: =Baserun_Full!AF8 -> 89.333333 | AC9: =Baserun_Full!AG8 -> 78.666667 | AD9: =Baserun_Full!AH8 -> 81.5 | AE9: =Baserun_Full!AI8 -> 79.666667 | AF9: =Baserun_Full!AJ8 -> 78.833333 | AG9: =Aware_Full!AF8 -> 77.833333 | AH9: =Aware_Full!AG8 -> 87.333333 | AI9: =Aware_Full!AH8 -> 87.5 | AJ9: =Aware_Full!AI8 -> 76.5 | AK9: =Aware_Full!AJ8 -> 78 | AL9: =Learn_Full!AF8 -> 86 | AM9: =Learn_Full!AG8 -> 84.833333 | AN9: =Learn_Full!AH8 -> 69.333333 | AO9: =Learn_Full!AI8 -> 70.166667 | AP9: =Learn_Full!AJ8 -> 73.333333 | AQ9: =Rich_Full!AF8 -> 81.666667 | AR9: =Rich_Full!AG8 -> 87.5 | AS9: =Rich_Full!AH8 -> 81.333333 | AT9: =Rich_Full!AI8 -> 80.166667 | AU9: =Rich_Full!AJ8 -> 79 | AW9: =PERCENTILE(AB9:AP9,0.25)/100 -> 0.77166667 | AX9: =PERCENTILE(AB9:AP9,0.5)/100 -> 0.78833333 | AY9: =PERCENTILE(AB9:AP9,0.75)/100 -> 0.85416667
A10: =Baserun_Full!A9 -> 6 | B10: =Baserun_Full!L9 -> 37 | C10: =Baserun_Full!M9 -> 28 | D10: =Baserun_Full!N9 -> 37 | E10: =Baserun_Full!O9 -> 34 | F10: =Baserun_Full!P9 -> 29 | G10: =Aware_Full!L9 -> 33 | H10: =Aware_Full!M9 -> 99 | I10: =Aware_Full!N9 -> 50 | J10: =Aware_Full!O9 -> 28 | K10: =Aware_Full!P9 -> 20 | L10: =Learn_Full!L9 -> 23 | M10: =Learn_Full!M9 -> 20 | N10: =Learn_Full!N9 -> 16 | O10: =Learn_Full!O9 -> 15 | P10: =Learn_Full!P9 -> 18 | Q10: =Rich_Full!L9 -> 47 | R10: =Rich_Full!M9 -> 51 | S10: =Rich_Full!N9 -> 93 | T10: =Rich_Full!O9 -> 40 | U10: =Rich_Full!P9 -> 45 | W10: =PERCENTILE(B10:P10,0.25) -> 20 | X10: =PERCENTILE(B10:P10,0.5) -> 28 | Y10: =PERCENTILE(B10:P10,0.75) -> 35.5 | AA10: =Baserun_Full!AE9 -> 6 | AB10: =Baserun_Full!AF9 -> 78.833333 | AC10: =Baserun_Full!AG9 -> 66.666667 | AD10: =Baserun_Full!AH9 -> 71 | AE10: =Baserun_Full!AI9 -> 68.666667 | AF10: =Baserun_Full!AJ9 -> 67 | AG10: =Aware_Full!AF9 -> 66.666667 | AH10: =Aware_Full!AG9 -> 87.166667 | AI10: =Aware_Full!AH9 -> 79.166667 | AJ10: =Aware_Full!AI9 -> 64.5 | AK10: =Aware_Full!AJ9 -> 64.666667 | AL10: =Learn_Full!AF9 -> 73.166667 | AM10: =Learn_Full!AG9 -> 71.5 | AN10: =Learn_Full!AH9 -> 55.333333 | AO10: =Learn_Full!AI9 -> 56 | AP10: =Learn_Full!AJ9 -> 59.666667 | AQ10: =Rich_Full!AF9 -> 72.833333 | AR10: =Rich_Full!AG9 -> 79.333333 | AS10: =Rich_Full!AH9 -> 80.166667 | AT10: =Rich_Full!AI9 -> 70.166667 | AU10: =Rich_Full!AJ9 -> 69.833333 | AW10: =PERCENTILE(AB10:AP10,0.25)/100 -> 0.64583333 | AX10: =PERCENTILE(AB10:AP10,0.5)/100 -> 0.67 | AY10: =PERCENTILE(AB10:AP10,0.75)/100 -> 0.72333333
A11: =Baserun_Full!A10 -> 7 | B11: =Baserun_Full!L10 -> 30 | C11: =Baserun_Full!M10 -> 14 | D11: =Baserun_Full!N10 -> 34 | E11: =Baserun_Full!O10 -> 30 | F11: =Baserun_Full!P10 -> 26 | G11: =Aware_Full!L10 -> 25 | H11: =Aware_Full!M10 -> 61 | I11: =Aware_Full!N10 -> 30 | J11: =Aware_Full!O10 -> 33 | K11: =Aware_Full!P10 -> 20 | L11: =Learn_Full!L10 -> 14 | M11: =Learn_Full!M10 -> 13 | N11: =Learn_Full!N10 -> 10 | O11: =Learn_Full!O10 -> 14 | P11: =Learn_Full!P10 -> 19 | Q11: =Rich_Full!L10 -> 49 | R11: =Rich_Full!M10 -> 49 | S11: =Rich_Full!N10 -> 93 | T11: =Rich_Full!O10 -> 36 | U11: =Rich_Full!P10 -> 54 | W11: =PERCENTILE(B11:P11,0.25) -> 14 | X11: =PERCENTILE(B11:P11,0.5) -> 25 | Y11: =PERCENTILE(B11:P11,0.75) -> 30 | AA11: =Baserun_Full!AE10 -> 7 | AB11: =Baserun_Full!AF10 -> 67.166667 | AC11: =Baserun_Full!AG10 -> 52.333333 | AD11: =Baserun_Full!AH10 -> 60 | AE11: =Baserun_Full!AI10 -> 57 | AF11: =Baserun_Full!AJ10 -> 54.833333 | AG11: =Aware_Full!AF10 -> 54.166667 | AH11: =Aware_Full!AG10 -> 80.666667 | AI11: =Aware_Full!AH10 -> 67.5 | AJ11: =Aware_Full!AI10 -> 53.333333 | AK11: =Aware_Full!AJ10 -> 51.333333 | AL11: =Learn_Full!AF10 -> 58.833333 | AM11: =Learn_Full!AG10 -> 57 | AN11: =Learn_Full!AH10 -> 40.666667 | AO11: =Learn_Full!AI10 -> 42 | AP11: =Learn_Full!AJ10 -> 46.5 | AQ11: =Rich_Full!AF10 -> 64.5 | AR11: =Rich_Full!AG10 -> 71.166667 | AS11: =Rich_Full!AH10 -> 79.833333 | AT11: =Rich_Full!AI10 -> 59.833333 | AU11: =Rich_Full!AJ10 -> 62.5 | AW11: =PERCENTILE(AB11:AP11,0.25)/100 -> 0.51833333 | AX11: =PERCENTILE(AB11:AP11,0.5)/100 -> 0.54833333 | AY11: =PERCENTILE(AB11:AP11,0.75)/100 -> 0.59416667
